Workbook

Sheet General
B2: BC | C2: Campana | F2: Mobile | L2: Digital
C3: Meta | D3: Resultado | E3: % Result | F3: Meta Activation | G3: Meta MNP | H3: Result Activation | I3: Result MNP | J3: % Result Active | K3: % Result MNP | L3: Meta Usuarios Bipay | M3: Meta TV360 | N3: Resultado Usuarios Bipay | O3: Resultado TV360 | P3: % Resultado Usuarios Bipay | Q3: % Resultado TV360
B4: LI3BC12 | C4: =COUNTIFS('Plan CP'!B:B,General!B4) -> 7 | D4: =COUNTIFS('Plan CP'!B:B,General!B4,'Plan CP'!R:R,"OK") -> 3 | E4: =D4/C4 -> 0.42857143 | F4: =SUMIFS('Plan CP'!T:T,'Plan CP'!B:B,General!B4)+SUMIFS('Plan CP'!U:U,'Plan CP'!B:B,General!B4) -> 195 | G4: =SUMIFS('Plan CP'!X:X,'Plan CP'!B:B,General!B4) -> 28 | H4: =SUMIFS('Plan CP'!AV:AV,'Plan CP'!B:B,General!B4)+SUMIFS('Plan CP'!AW:AW,'Plan CP'!B:B,General!B4) -> 77 | I4: =SUMIFS('Plan CP'!AZ:AZ,'Plan CP'!B:B,General!B4) -> 14 | J4: =H4/F4 -> 0.39487179 | K4: =I4/G4 -> 0.5 | L4: =SUMIFS('Plan CP'!Z:Z,'Plan CP'!B:B,General!B4) -> 30 | M4: =SUMIFS('Plan CP'!W:W,'Plan CP'!B:B,General!B4) -> 46 | N4: =SUMIFS('Plan CP'!B:B,'Plan CP'!B:B,General!B4) -> 0 | O4: =SUMIFS('Plan CP'!AI:AI,'Plan CP'!B:B,General!B4) -> 35 | P4: =IFERROR(N4/L4,0) -> 0 | Q4: =O4/M4 -> 0.76086957
B5: LI3BC11 | C5: =COUNTIFS('Plan CP'!B:B,General!B5) -> 2 | D5: =COUNTIFS('Plan CP'!B:B,General!B5,'Plan CP'!R:R,"OK") -> 1 | E5: =D5/C5 -> 0.5 | F5: =SUMIFS('Plan CP'!T:T,'Plan CP'!B:B,General!B5)+SUMIFS('Plan CP'!U:U,'Plan CP'!B:B,General!B5) -> 50 | G5: =SUMIFS('Plan CP'!X:X,'Plan CP'!B:B,General!B5) -> 8 | H5: =SUMIFS('Plan CP'!AV:AV,'Plan CP'!B:B,General!B5)+SUMIFS('Plan CP'!AW:AW,'Plan CP'!B:B,General!B5) -> 22 | I5: =SUMIFS('Plan CP'!AZ:AZ,'Plan CP'!B:B,General!B5) -> 4 | J5: =H5/F5 -> 0.44 | K5: =I5/G5 -> 0.5 | L5: =SUMIFS('Plan CP'!Z:Z,'Plan CP'!B:B,General!B5) -> 0 | M5: =SUMIFS('Plan CP'!W:W,'Plan CP'!B:B,General!B5) -> 17 | N5: =SUMIFS('Plan CP'!B:B,'Plan CP'!B:B,General!B5) -> 0 | O5: =SUMIFS('Plan CP'!AI:AI,'Plan CP'!B:B,General!B5) -> 10 | P5: =IFERROR(N5/L5,0) -> 0 | Q5: =O5/M5 -> 0.58823529
B6: LI3BC06 | C6: =COUNTIFS('Plan CP'!B:B,General!B6) -> 14 | D6: =COUNTIFS('Plan CP'!B:B,General!B6,'Plan CP'!R:R,"OK") -> 6 | E6: =D6/C6 -> 0.42857143 | F6: =SUMIFS('Plan CP'!T:T,'Plan CP'!B:B,General!B6)+SUMIFS('Plan CP'!U:U,'Plan CP'!B:B,General!B6) -> 426 | G6: =SUMIFS('Plan CP'!X:X,'Plan CP'!B:B,General!B6) -> 60 | H6: =SUMIFS('Plan CP'!AV:AV,'Plan CP'!B:B,General!B6)+SUMIFS('Plan CP'!AW:AW,'Plan CP'!B:B,General!B6) -> 154 | I6: =SUMIFS('Plan CP'!AZ:AZ,'Plan CP'!B:B,General!B6) -> 28 | J6: =H6/F6 -> 0.36150235 | K6: =I6/G6 -> 0.46666667 | L6: =SUMIFS('Plan CP'!Z:Z,'Plan CP'!B:B,General!B6) -> 60 | M6: =SUMIFS('Plan CP'!W:W,'Plan CP'!B:B,General!B6) -> 96 | N6: =SUMIFS('Plan CP'!B:B,'Plan CP'!B:B,General!B6) -> 0 | O6: =SUMIFS('Plan CP'!AI:AI,'Plan CP'!B:B,General!B6) -> 70 | P6: =IFERROR(N6/L6,0) -> 0 | Q6: =O6/M6 -> 0.72916667
B7: LI3BC03 | C7: =COUNTIFS('Plan CP'!B:B,General!B7) -> 10 | D7: =COUNTIFS('Plan CP'!B:B,General!B7,'Plan CP'!R:R,"OK") -> 4 | E7: =D7/C7 -> 0.4 | F7: =SUMIFS('Plan CP'!T:T,'Plan CP'!B:B,General!B7)+SUMIFS('Plan CP'!U:U,'Plan CP'!B:B,General!B7) -> 294 | G7: =SUMIFS('Plan CP'!X:X,'Plan CP'!B:B,General!B7) -> 42 | H7: =SUMIFS('Plan CP'!AV:AV,'Plan CP'!B:B,General!B7)+SUMIFS('Plan CP'!AW:AW,'Plan CP'!B:B,General!B7) -> 110 | I7: =SUMIFS('Plan CP'!AZ:AZ,'Plan CP'!B:B,General!B7) -> 20 | J7: =H7/F7 -> 0.37414966 | K7: =I7/G7 -> 0.47619048 | L7: =SUMIFS('Plan CP'!Z:Z,'Plan CP'!B:B,General!B7) -> 15 | M7: =SUMIFS('Plan CP'!W:W,'Plan CP'!B:B,General!B7) -> 69 | N7: =SUMIFS('Plan CP'!B:B,'Plan CP'!B:B,General!B7) -> 0 | O7: =SUMIFS('Plan CP'!AI:AI,'Plan CP'!B:B,General!B7) -> 50 | P7: =IFERROR(N7/L7,0) -> 0 | Q7: =O7/M7 -> 0.72463768
B8: LI3BC07 | C8: =COUNTIFS('Plan CP'!B:B,General!B8) -> 3 | D8: =COUNTIFS('Plan CP'!B:B,General!B8,'Plan CP'!R:R,"OK") -> 2 | E8: =D8/C8 -> 0.66666667 | F8: =SUMIFS('Plan CP'!T:T,'Plan CP'!B:B,General!B8)+SUMIFS('Plan CP'!U:U,'Plan CP'!B:B,General!B8) -> 67 | G8: =SUMIFS('Plan CP'!X:X,'Plan CP'!B:B,General!B8) -> 12 | H8: =SUMIFS('Plan CP'!AV:AV,'Plan CP'!B:B,General!B8)+SUMIFS('Plan CP'!AW:AW,'Plan CP'!B:B,General!B8) -> 33 | I8: =SUMIFS('Plan CP'!AZ:AZ,'Plan CP'!B:B,General!B8) -> 6 | J8: =H8/F8 -> 0.49253731 | K8: =I8/G8 -> 0.5 | L8: =SUMIFS('Plan CP'!Z:Z,'Plan CP'!B:B,General!B8) -> 0 | M8: =SUMIFS('Plan CP'!W:W,'Plan CP'!B:B,General!B8) -> 30 | N8: =SUMIFS('Plan CP'!B:B,'Plan CP'!B:B,General!B8) -> 0 | O8: =SUMIFS('Plan CP'!AI:AI,'Plan CP'!B:B,General!B8) -> 15 | P8: =IFERROR(N8/L8,0) -> 0 | Q8: =O8/M8 -> 0.5
B9: LI2BC13 | C9: =COUNTIFS('Plan CP'!B:B,General!B9) -> 7 | D9: =COUNTIFS('Plan CP'!B:B,General!B9,'Plan CP'!R:R,"OK") -> 5 | E9: =D9/C9 -> 0.71428571 | F9: =SUMIFS('Plan CP'!T:T,'Plan CP'!B:B,General!B9)+SUMIFS('Plan CP'!U:U,'Plan CP'!B:B,General!B9) -> 220 | G9: =SUMIFS('Plan CP'!X:X,'Plan CP'!B:B,General!B9) -> 31 | H9: =SUMIFS('Plan CP'!AV:AV,'Plan CP'!B:B,General!B9)+SUMIFS('Plan CP'!AW:AW,'Plan CP'!B:B,General!B9) -> 77 | I9: =SUMIFS('Plan CP'!AZ:AZ,'Plan CP'!B:B,General!B9) -> 14 | J9: =H9/F9 -> 0.35 | K9: =I9/G9 -> 0.4516129 | L9: =SUMIFS('Plan CP'!Z:Z,'Plan CP'!B:B,General!B9) -> 45 | M9: =SUMIFS('Plan CP'!W:W,'Plan CP'!B:B,General!B9) -> 49 | N9: =SUMIFS('Plan CP'!B:B,'Plan CP'!B:B,General!B9) -> 0 | O9: =SUMIFS('Plan CP'!AI:AI,'Plan CP'!B:B,General!B9) -> 35 | P9: =IFERROR(N9/L9,0) -> 0 | Q9: =O9/M9 -> 0.71428571
B10: LI3BC10 | C10: =COUNTIFS('Plan CP'!B:B,General!B10) -> 8 | D10: =COUNTIFS('Plan CP'!B:B,General!B10,'Plan CP'!R:R,"OK") -> 1 | E10: =D10/C10 -> 0.125 | F10: =SUMIFS('Plan CP'!T:T,'Plan CP'!B:B,General!B10)+SUMIFS('Plan CP'!U:U,'Plan CP'!B:B,General!B10) -> 258 | G10: =SUMIFS('Plan CP'!X:X,'Plan CP'!B:B,General!B10) -> 36 | H10: =SUMIFS('Plan CP'!AV:AV,'Plan CP'!B:B,General!B10)+SUMIFS('Plan CP'!AW:AW,'Plan CP'!B:B,General!B10) -> 88 | I10: =SUMIFS('Plan CP'!AZ:AZ,'Plan CP'!B:B,General!B10) -> 16 | J10: =H10/F10 -> 0.34108527 | K10: =I10/G10 -> 0.44444444 | L10: =SUMIFS('Plan CP'!Z:Z,'Plan CP'!B:B,General!B10) -> 45 | M10: =SUMIFS('Plan CP'!W:W,'Plan CP'!B:B,General!B10) -> 54 | N10: =SUMIFS('Plan CP'!B:B,'Plan CP'!B:B,General!B10) -> 0 | O10: =SUMIFS('Plan CP'!AI:AI,'Plan CP'!B:B,General!B10) -> 40 | P10: =IFERROR(N10/L10,0) -> 0 | Q10: =O10/M10 -> 0.74074074
B11: LI3BC08 | C11: =COUNTIFS('Plan CP'!B:B,General!B11) -> 16 | D11: =COUNTIFS('Plan CP'!B:B,General!B11,'Plan CP'!R:R,"OK") -> 7 | E11: =D11/C11 -> 0.4375 | F11: =SUMIFS('Plan CP'!T:T,'Plan CP'!B:B,General!B11)+SUMIFS('Plan CP'!U:U,'Plan CP'!B:B,General!B11) -> 509 | G11: =SUMIFS('Plan CP'!X:X,'Plan CP'!B:B,General!B11) -> 73 | H11: =SUMIFS('Plan CP'!AV:AV,'Plan CP'!B:B,General!B11)+SUMIFS('Plan CP'!AW:AW,'Plan CP'!B:B,General!B11) -> 176 | I11: =SUMIFS('Plan CP'!AZ:AZ,'Plan CP'!B:B,General!B11) -> 32 | J11: =H11/F11 -> 0.34577603 | K11: =I11/G11 -> 0.43835616 | L11: =SUMIFS('Plan CP'!Z:Z,'Plan CP'!B:B,General!B11) -> 120 | M11: =SUMIFS('Plan CP'!W:W,'Plan CP'!B:B,General!B11) -> 118 | N11: =SUMIFS('Plan CP'!B:B,'Plan CP'!B:B,General!B11) -> 0 | O11: =SUMIFS('Plan CP'!AI:AI,'Plan CP'!B:B,General!B11) -> 80 | P11: =IFERROR(N11/L11,0) -> 0 | Q11: =O11/M11 -> 0.6779661
B12: LI2BC11 | C12: =COUNTIFS('Plan CP'!B:B,General!B12) -> 14 | D12: =COUNTIFS('Plan CP'!B:B,General!B12,'Plan CP'!R:R,"OK") -> 4 | E12: =D12/C12 -> 0.28571429 | F12: =SUMIFS('Plan CP'!T:T,'Plan CP'!B:B,General!B12)+SUMIFS('Plan CP'!U:U,'Plan CP'!B:B,General!B12) -> 405 | G12: =SUMIFS('Plan CP'!X:X,'Plan CP'!B:B,General!B12) -> 57 | H12: =SUMIFS('Plan CP'!AV:AV,'Plan CP'!B:B,General!B12)+SUMIFS('Plan CP'!AW:AW,'Plan CP'!B:B,General!B12) -> 154 | I12: =SUMIFS('Plan CP'!AZ:AZ,'Plan CP'!B:B,General!B12) -> 28 | J12: =H12/F12 -> 0.38024691 | K12: =I12/G12 -> 0.49122807 | L12: =SUMIFS('Plan CP'!Z:Z,'Plan CP'!B:B,General!B12) -> 60 | M12: =SUMIFS('Plan CP'!W:W,'Plan CP'!B:B,General!B12) -> 93 | N12: =SUMIFS('Plan CP'!B:B,'Plan CP'!B:B,General!B12) -> 0 | O12: =SUMIFS('Plan CP'!AI:AI,'Plan CP'!B:B,General!B12) -> 70 | P12: =IFERROR(N12/L12,0) -> 0 | Q12: =O12/M12 -> 0.75268817
B13: Total | C13: =SUM(C4:C12) -> 81 | D13: =SUM(D4:D12) -> 33 | E13: =D13/C13 -> 0.40740741 | F13: =SUM(F4:F12) -> 2424 | G13: =SUM(G4:G12) -> 347 | H13: =SUM(H4:H12) -> 891 | I13: =SUM(I4:I12) -> 162 | J13: =H13/F13 -> 0.36757426 | K13: =I13/G13 -> 0.46685879 | L13: =SUM(L4:L12) -> 375 | M13: =SUM(M4:M12) -> 572 | N13: =SUM(N4:N12) -> 0 | O13: =SUM(O4:O12) -> 405 | P13: =IFERROR(N13/L13,0) -> 0 | Q13: =O13/M13 -> 0.70804196

Sheet Plan CP
A1: =TODAY() -> 46154
A5: No tocar | L5: Input here | Q5: No tocar | T5: Meta | AC5: Gasto | AH5: Merchadising | AM5: % Resultado | AV5: Resultado | BE5: Assistente Check and Note
A6: BR | B6: BC | C6: DEPARTAMENTO | D6: DISTRITO | E6: Tipo DF/CP | F6: Horario traffico | G6: Fecha Alta Traffico | H6: Prioridad | I6: Latitud | J6: Longitud | K6: Check | L6: Code Ubicacion | M6: Cantidad día hacer campaña | N6: People InCharge | O6: Grupo/Code PR | P6: Start Date | Q6: End | R6: Overtime/ Ontime | S6: Check Traffic day | T6: Prepago | U6: Postpago | V6: Bipay cashin 20% (minimo 5 soles) | W6: TV360 | X6: MNP | Y6: Creacion de Agentes/Negocio | Z6: Usuarios Bipay | AA6: Pago de Servicios | AB6: Meta Tusami | AC6: Pago Comida | AD6: Pago Hotel | AE6: Pago Movilidad | AF6: Pago Renta Local | AG6: Gasto total | AH6: Bolígrafo | AI6: Taza | AJ6: LLavero | AK6: Papin | AL6: Sombrero | AM6: Prepago | AN6: Postpago | AO6: Bipay cashin 20% (minimo 5 soles) | AP6: TV360 | AQ6: MNP | AR6: Creacion de Agentes/Negocio | AS6: Usuarios Bipay | AT6: Pago de Servicios | AU6: Meta Tusami | AV6: Prepago | AW6: Postpago | AX6: Bipay cashin 20% (minimo 5 soles) | AY6: TV360 | AZ6: MNP | BA6: Creacion de Agentes/Negocio | BB6: Usuarios Bipay | BC6: Pago de Servicios | BD6: Meta Tusami | BE6: ENVIDENCIA DE PAGA Gatos | BF6: Merchandising | BG6: CAMPAÑA CHECKLIST (Gente, MKT) | BH6: CUMPLE ACTIVACIONES | BI6: Cumple Digital | BJ6: CAMPAÑA OK | BK6: DFCode/BTS Code | BL6: Nota | BN6: ='PR Grupo'!A1 -> 46143 | BO6: =BN6+1 -> 46144 | BP6: =BO6+1 -> 46145 | BQ6: =BP6+1 -> 46146 | BR6: =BQ6+1 -> 46147 | BS6: =BR6+1 -> 46148 | BT6: =BS6+1 -> 46149 | BU6: =BT6+1 -> 46150 | BV6: =BU6+1 -> 46151 | ... CR6: =CQ6+1 -> 46173
A7: =VLOOKUP(L7,Ubicacion!A:K,2,FALSE) -> LI3BR | B7: =VLOOKUP(L7,Ubicacion!A:K,3,FALSE) -> LI3BC12 | C7: =VLOOKUP(L7,Ubicacion!A:K,4,FALSE) -> LIMA | D7: =VLOOKUP(L7,Ubicacion!A:K,5,FALSE) -> SURCO | E7: =VLOOKUP(L7,Ubicacion!A:K,6,FALSE) -> DF Fijo | F7: =VLOOKUP(L7,Ubicacion!A:K,7,FALSE) -> 16:00 - 19:00 | G7: =VLOOKUP(L7,Ubicacion!A:K,8,FALSE) -> WEEKDAY | H7: =VLOOKUP(L7,Ubicacion!A:K,9,FALSE) -> 1 | I7: =VLOOKUP(L7,Ubicacion!A:K,10,FALSE) -> -12.140921 | J7: =VLOOKUP(L7,Ubicacion!A:K,11,FALSE) -> -76.995037 | K7: =P7&O7 -> 46143LI3PR10136 | L7: CP01 | M7: 10 | N7: JBC | O7: LI3PR10136 | P7: 46143 | Q7: =P7+M7-1 -> 46152 | R7: =IF($A$1<Q7,"On-time",IF(AND(Q7<=$A$1,BJ7="OK"),"OK","NO OK")) -> OK | S7: =(UPPER(TEXT(P7,"dddd"))) -> FRIDAY | T7: =VLOOKUP(L7,Ubicacion!A:AE,13,FALSE) -> 15 | U7: =VLOOKUP(L7,Ubicacion!A:AE,14,FALSE) -> 2 | V7: =VLOOKUP(L7,Ubicacion!A:AE,15,FALSE) -> 2 | W7: =VLOOKUP(L7,Ubicacion!A:AE,16,FALSE) -> 13 | X7: =VLOOKUP(L7,Ubicacion!A:AE,17,FALSE) -> 4 | Y7: =VLOOKUP(L7,Ubicacion!A:AE,18,FALSE) -> 4 | Z7: =VLOOKUP(L7,Ubicacion!A:AE,19,FALSE) -> 0 | AA7: =VLOOKUP(L7,Ubicacion!A:AE,20,FALSE) -> 0 | AB7: 1 | AC7: =VLOOKUP(L7,Ubicacion!A:AE,22,FALSE) -> 2 | AD7: =VLOOKUP(L7,Ubicacion!A:AE,23,FALSE) -> 0 | AE7: =VLOOKUP(L7,Ubicacion!A:AE,24,FALSE) -> 0 | AF7: =VLOOKUP(L7,Ubicacion!A:AE,25,FALSE) -> 0 | AG7: =VLOOKUP(L7,Ubicacion!A:AE,26,FALSE) -> 2 | AH7: =VLOOKUP(L7,Ubicacion!A:AE,27,FALSE) -> 2 | AI7: =VLOOKUP(L7,Ubicacion!A:AE,28,FALSE) -> 5 | AJ7: =VLOOKUP(L7,Ubicacion!A:AE,29,FALSE) -> 3 | AK7: =VLOOKUP(L7,Ubicacion!A:AE,30,FALSE) -> 1 | AL7: =VLOOKUP(L7,Ubicacion!A:AE,31,FALSE) -> 1 | AM7: =IF(T7=0,"100%",AV7/T7) -> 0.66666667 | AN7: =IF(U7=0,"100%",AW7/U7) -> 0.5 | AO7: =IF(V7=0,"100%",AX7/V7) -> 1 | AP7: =IF(W7=0,"100%",AY7/W7) -> 0.15384615 | AQ7: =IF(X7=0,"100%",AZ7/X7) -> 0.5 | AR7: =IF(Y7=0,"100%",BA7/Y7) -> 0.25 | AS7: =IF(Z7=0,"100%",BB7/Z7) -> 100% | AT7: =IF(AA7=0,"100%",BC7/AA7) -> 100% | AU7: =IF(AB7=0,"100%",BD7/AB7) -> 0 | AV7: 10 | AW7: 1 | AX7: 2 | AY7: 2 | AZ7: 2 | BA7: 1 | BB7: 2 | BC7: 1 | BD7: 0 | BE7: NO OK | BF7: NO OK | BG7: OK | BH7: OK | BI7: OK | BJ7: OK | BK7: LI3DF9 | BN7: =IF(AND((BN$6-$P7)>=0,(BN$6-$P7)<=($Q7-$P7)),"."," ") -> . | BO7: =IF(AND((BO$6-$P7)>=0,(BO$6-$P7)<=($Q7-$P7)),"."," ") -> . | BP7: =IF(AND((BP$6-$P7)>=0,(BP$6-$P7)<=($Q7-$P7)),"."," ") -> . | BQ7: =IF(AND((BQ$6-$P7)>=0,(BQ$6-$P7)<=($Q7-$P7)),"."," ") -> . | BR7: =IF(AND((BR$6-$P7)>=0,(BR$6-$P7)<=($Q7-$P7)),"."," ") -> . | BS7: =IF(AND((BS$6-$P7)>=0,(BS$6-$P7)<=($Q7-$P7)),"."," ") -> . | BT7: =IF(AND((BT$6-$P7)>=0,(BT$6-$P7)<=($Q7-$P7)),"."," ") -> . | BU7: =IF(AND((BU$6-$P7)>=0,(BU$6-$P7)<=($Q7-$P7)),"."," ") -> . | ... CR7: =IF(AND((CR$6-$P7)>=0,(CR$6-$P7)<=($Q7-$P7)),"."," ")
A8: =VLOOKUP(L8,Ubicacion!A:K,2,FALSE) -> LI3BR | B8: =VLOOKUP(L8,Ubicacion!A:K,3,FALSE) -> LI3BC12 | C8: =VLOOKUP(L8,Ubicacion!A:K,4,FALSE) -> LIMA | D8: =VLOOKUP(L8,Ubicacion!A:K,5,FALSE) -> SURCO | E8: =VLOOKUP(L8,Ubicacion!A:K,6,FALSE) -> DF Fijo | F8: =VLOOKUP(L8,Ubicacion!A:K,7,FALSE) -> 16:00 - 19:00 | G8: =VLOOKUP(L8,Ubicacion!A:K,8,FALSE) -> WEEKDAY | H8: =VLOOKUP(L8,Ubicacion!A:K,9,FALSE) -> 1 | I8: =VLOOKUP(L8,Ubicacion!A:K,10,FALSE) -> -12.140921 | J8: =VLOOKUP(L8,Ubicacion!A:K,11,FALSE) -> -76.995037 | K8: =P8&O8 -> 46143Grupo 1 | L8: CP01 | M8: 2 | N8: AF | O8: Grupo 1 | P8: 46143 | Q8: =P8+M8-1 -> 46144 | R8: =IF($A$1<Q8,"On-time",IF(AND(Q8<=$A$1,BJ8="OK"),"OK","NO OK")) -> NO OK | S8: =(UPPER(TEXT(P8,"dddd"))) -> FRIDAY | T8: =VLOOKUP(L8,Ubicacion!A:AE,13,FALSE) -> 15 | U8: =VLOOKUP(L8,Ubicacion!A:AE,14,FALSE) -> 2 | V8: =VLOOKUP(L8,Ubicacion!A:AE,15,FALSE) -> 2 | W8: =VLOOKUP(L8,Ubicacion!A:AE,16,FALSE) -> 13 | X8: =VLOOKUP(L8,Ubicacion!A:AE,17,FALSE) -> 4 | Y8: =VLOOKUP(L8,Ubicacion!A:AE,18,FALSE) -> 4 | Z8: =VLOOKUP(L8,Ubicacion!A:AE,19,FALSE) -> 0 | AA8: =VLOOKUP(L8,Ubicacion!A:AE,20,FALSE) -> 0 | AB8: =VLOOKUP(L8,Ubicacion!A:AE,21,FALSE) -> 0 | AC8: =VLOOKUP(L8,Ubicacion!A:AE,22,FALSE) -> 2 | AD8: =VLOOKUP(L8,Ubicacion!A:AE,23,FALSE) -> 0 | AE8: =VLOOKUP(L8,Ubicacion!A:AE,24,FALSE) -> 0 | AF8: =VLOOKUP(L8,Ubicacion!A:AE,25,FALSE) -> 0 | AG8: =VLOOKUP(L8,Ubicacion!A:AE,26,FALSE) -> 2 | AH8: =VLOOKUP(L8,Ubicacion!A:AE,27,FALSE) -> 2 | AI8: =VLOOKUP(L8,Ubicacion!A:AE,28,FALSE) -> 5 | AJ8: =VLOOKUP(L8,Ubicacion!A:AE,29,FALSE) -> 3 | AK8: =VLOOKUP(L8,Ubicacion!A:AE,30,FALSE) -> 1 | AL8: =VLOOKUP(L8,Ubicacion!A:AE,31,FALSE) -> 1 | AM8: =IF(T8=0,"100%",AV8/T8) -> 0.66666667 | AN8: =IF(U8=0,"100%",AW8/U8) -> 0.5 | AO8: =IF(V8=0,"100%",AX8/V8) -> 1 | AP8: =IF(W8=0,"100%",AY8/W8) -> 0.15384615 | AQ8: =IF(X8=0,"100%",AZ8/X8) -> 0.5 | AR8: =IF(Y8=0,"100%",BA8/Y8) -> 0.25 | AS8: =IF(Z8=0,"100%",BB8/Z8) -> 100% | AT8: =IF(AA8=0,"100%",BC8/AA8) -> 100% | AU8: =IF(AB8=0,"100%",BD8/AB8) -> 100% | AV8: 10 | AW8: 1 | AX8: 2 | AY8: 2 | AZ8: 2 | BA8: 1 | BB8: 2 | BC8: 1 | BD8: 1 | BE8: NO OK | BF8: NO OK | BG8: OK | BH8: OK | BI8: OK | BJ8: NO OK | BN8: =IF(AND((BN$6-$P8)>=0,(BN$6-$P8)<=($Q8-$P8)),"."," ") -> . | BO8: =IF(AND((BO$6-$P8)>=0,(BO$6-$P8)<=($Q8-$P8)),"."," ") -> . | BP8: =IF(AND((BP$6-$P8)>=0,(BP$6-$P8)<=($Q8-$P8)),"."," ") | BQ8: =IF(AND((BQ$6-$P8)>=0,(BQ$6-$P8)<=($Q8-$P8)),"."," ") | BR8: =IF(AND((BR$6-$P8)>=0,(BR$6-$P8)<=($Q8-$P8)),"."," ") | BS8: =IF(AND((BS$6-$P8)>=0,(BS$6-$P8)<=($Q8-$P8)),"."," ") | BT8: =IF(AND((BT$6-$P8)>=0,(BT$6-$P8)<=($Q8-$P8)),"."," ") | BU8: =IF(AND((BU$6-$P8)>=0,(BU$6-$P8)<=($Q8-$P8)),"."," ") | ... CR8: =IF(AND((CR$6-$P8)>=0,(CR$6-$P8)<=($Q8-$P8)),"."," ")
A9: =VLOOKUP(L9,Ubicacion!A:K,2,FALSE) -> LI3BR | B9: =VLOOKUP(L9,Ubicacion!A:K,3,FALSE) -> LI3BC06 | C9: =VLOOKUP(L9,Ubicacion!A:K,4,FALSE) -> LIMA | D9: =VLOOKUP(L9,Ubicacion!A:K,5,FALSE) -> SURCO | E9: =VLOOKUP(L9,Ubicacion!A:K,6,FALSE) -> Zone 5% | F9: =VLOOKUP(L9,Ubicacion!A:K,7,FALSE) -> 8:00 - 16:00 | G9: =VLOOKUP(L9,Ubicacion!A:K,8,FALSE) -> SUNDAY | H9: =VLOOKUP(L9,Ubicacion!A:K,9,FALSE) -> 1 | I9: =VLOOKUP(L9,Ubicacion!A:K,10,FALSE) -> -12.100791 | J9: =VLOOKUP(L9,Ubicacion!A:K,11,FALSE) -> -76.971543 | K9: =P9&O9 -> 46144Grupo 1 | L9: CP03 | M9: 3 | N9: SUB-BC | O9: Grupo 1 | P9: 46144 | Q9: =P9+M9-1 -> 46146 | R9: =IF($A$1<Q9,"On-time",IF(AND(Q9<=$A$1,BJ9="OK"),"OK","NO OK")) -> OK | S9: =(UPPER(TEXT(P9,"dddd"))) -> SATURDAY | T9: =VLOOKUP(L9,Ubicacion!A:AE,13,FALSE) -> 15 | U9: =VLOOKUP(L9,Ubicacion!A:AE,14,FALSE) -> 2 | V9: =VLOOKUP(L9,Ubicacion!A:AE,15,FALSE) -> 2 | W9: =VLOOKUP(L9,Ubicacion!A:AE,16,FALSE) -> 13 | X9: =VLOOKUP(L9,Ubicacion!A:AE,17,FALSE) -> 4 | Y9: =VLOOKUP(L9,Ubicacion!A:AE,18,FALSE) -> 4 | Z9: =VLOOKUP(L9,Ubicacion!A:AE,19,FALSE) -> 0 | AA9: =VLOOKUP(L9,Ubicacion!A:AE,20,FALSE) -> 0 | AB9: =VLOOKUP(L9,Ubicacion!A:AE,21,FALSE) -> 0 | AC9: =VLOOKUP(L9,Ubicacion!A:AE,22,FALSE) -> 2 | AD9: =VLOOKUP(L9,Ubicacion!A:AE,23,FALSE) -> 0 | AE9: =VLOOKUP(L9,Ubicacion!A:AE,24,FALSE) -> 0 | AF9: =VLOOKUP(L9,Ubicacion!A:AE,25,FALSE) -> 0 | AG9: =VLOOKUP(L9,Ubicacion!A:AE,26,FALSE) -> 2 | AH9: =VLOOKUP(L9,Ubicacion!A:AE,27,FALSE) -> 2 | AI9: =VLOOKUP(L9,Ubicacion!A:AE,28,FALSE) -> 5 | AJ9: =VLOOKUP(L9,Ubicacion!A:AE,29,FALSE) -> 3 | AK9: =VLOOKUP(L9,Ubicacion!A:AE,30,FALSE) -> 1 | AL9: =VLOOKUP(L9,Ubicacion!A:AE,31,FALSE) -> 1 | AM9: =IF(T9=0,"100%",AV9/T9) -> 0.66666667 | AN9: =IF(U9=0,"100%",AW9/U9) -> 0.5 | AO9: =IF(V9=0,"100%",AX9/V9) -> 1 | AP9: =IF(W9=0,"100%",AY9/W9) -> 0.15384615 | AQ9: =IF(X9=0,"100%",AZ9/X9) -> 0.5 | AR9: =IF(Y9=0,"100%",BA9/Y9) -> 0.25 | AS9: =IF(Z9=0,"100%",BB9/Z9) -> 100% | AT9: =IF(AA9=0,"100%",BC9/AA9) -> 100% | AU9: =IF(AB9=0,"100%",BD9/AB9) -> 100% | AV9: 10 | AW9: 1 | AX9: 2 | AY9: 2 | AZ9: 2 | BA9: 1 | BB9: 2 | BC9: 1 | BD9: 1 | BE9: NO OK | BF9: NO OK | BG9: OK | BH9: OK | BI9: OK | BJ9: OK | BN9: =IF(AND((BN$6-$P9)>=0,(BN$6-$P9)<=($Q9-$P9)),"."," ") | BO9: =IF(AND((BO$6-$P9)>=0,(BO$6-$P9)<=($Q9-$P9)),"."," ") -> . | BP9: =IF(AND((BP$6-$P9)>=0,(BP$6-$P9)<=($Q9-$P9)),"."," ") -> . | BQ9: =IF(AND((BQ$6-$P9)>=0,(BQ$6-$P9)<=($Q9-$P9)),"."," ") -> . | BR9: =IF(AND((BR$6-$P9)>=0,(BR$6-$P9)<=($Q9-$P9)),"."," ") | BS9: =IF(AND((BS$6-$P9)>=0,(BS$6-$P9)<=($Q9-$P9)),"."," ") | BT9: =IF(AND((BT$6-$P9)>=0,(BT$6-$P9)<=($Q9-$P9)),"."," ") | BU9: =IF(AND((BU$6-$P9)>=0,(BU$6-$P9)<=($Q9-$P9)),"."," ") | ... CR9: =IF(AND((CR$6-$P9)>=0,(CR$6-$P9)<=($Q9-$P9)),"."," ")
A10: =VLOOKUP(L10,Ubicacion!A:K,2,FALSE) -> LI3BR | B10: =VLOOKUP(L10,Ubicacion!A:K,3,FALSE) -> LI3BC06 | C10: =VLOOKUP(L10,Ubicacion!A:K,4,FALSE) -> LIMA | D10: =VLOOKUP(L10,Ubicacion!A:K,5,FALSE) -> SURCO | E10: =VLOOKUP(L10,Ubicacion!A:K,6,FALSE) -> Universidad | F10: =VLOOKUP(L10,Ubicacion!A:K,7,FALSE) -> 8:00 - 13:00 | G10: =VLOOKUP(L10,Ubicacion!A:K,8,FALSE) -> MONDAY | H10: =VLOOKUP(L10,Ubicacion!A:K,9,FALSE) -> 1 | I10: =VLOOKUP(L10,Ubicacion!A:K,10,FALSE) -> -12.130418 | J10: =VLOOKUP(L10,Ubicacion!A:K,11,FALSE) -> -76.980579 | K10: =P10&O10 -> 46145Grupo 3 | L10: CP04 | M10: 1 | N10: AF | O10: Grupo 3 | P10: 46145 | Q10: =P10+M10-1 -> 46145 | R10: =IF($A$1<Q10,"On-time",IF(AND(Q10<=$A$1,BJ10="OK"),"OK","NO OK")) -> NO OK | S10: =(UPPER(TEXT(P10,"dddd"))) -> SUNDAY | T10: =VLOOKUP(L10,Ubicacion!A:AE,13,FALSE) -> 15 | U10: =VLOOKUP(L10,Ubicacion!A:AE,14,FALSE) -> 2 | V10: =VLOOKUP(L10,Ubicacion!A:AE,15,FALSE) -> 2 | W10: =VLOOKUP(L10,Ubicacion!A:AE,16,FALSE) -> 13 | X10: =VLOOKUP(L10,Ubicacion!A:AE,17,FALSE) -> 4 | Y10: =VLOOKUP(L10,Ubicacion!A:AE,18,FALSE) -> 4 | Z10: =VLOOKUP(L10,Ubicacion!A:AE,19,FALSE) -> 0 | AA10: =VLOOKUP(L10,Ubicacion!A:AE,20,FALSE) -> 0 | AB10: =VLOOKUP(L10,Ubicacion!A:AE,21,FALSE) -> 0 | AC10: =VLOOKUP(L10,Ubicacion!A:AE,22,FALSE) -> 2 | AD10: =VLOOKUP(L10,Ubicacion!A:AE,23,FALSE) -> 0 | AE10: =VLOOKUP(L10,Ubicacion!A:AE,24,FALSE) -> 0 | AF10: =VLOOKUP(L10,Ubicacion!A:AE,25,FALSE) -> 0 | AG10: =VLOOKUP(L10,Ubicacion!A:AE,26,FALSE) -> 2 | AH10: =VLOOKUP(L10,Ubicacion!A:AE,27,FALSE) -> 2 | AI10: =VLOOKUP(L10,Ubicacion!A:AE,28,FALSE) -> 5 | AJ10: =VLOOKUP(L10,Ubicacion!A:AE,29,FALSE) -> 3 | AK10: =VLOOKUP(L10,Ubicacion!A:AE,30,FALSE) -> 1 | AL10: =VLOOKUP(L10,Ubicacion!A:AE,31,FALSE) -> 1 | AM10: =IF(T10=0,"100%",AV10/T10) -> 0.66666667 | AN10: =IF(U10=0,"100%",AW10/U10) -> 0.5 | AO10: =IF(V10=0,"100%",AX10/V10) -> 1 | AP10: =IF(W10=0,"100%",AY10/W10) -> 0.15384615 | AQ10: =IF(X10=0,"100%",AZ10/X10) -> 0.5 | AR10: =IF(Y10=0,"100%",BA10/Y10) -> 0.25 | AS10: =IF(Z10=0,"100%",BB10/Z10) -> 100% | AT10: =IF(AA10=0,"100%",BC10/AA10) -> 100% | AU10: =IF(AB10=0,"100%",BD10/AB10) -> 100% | AV10: 10 | AW10: 1 | AX10: 2 | AY10: 2 | AZ10: 2 | BA10: 1 | BB10: 2 | BC10: 1 | BD10: 1 | BE10: NO OK | BF10: NO OK | BG10: OK | BH10: OK | BI10: OK | BJ10: NO OK | BN10: =IF(AND((BN$6-$P10)>=0,(BN$6-$P10)<=($Q10-$P10)),"."," ") | BO10: =IF(AND((BO$6-$P10)>=0,(BO$6-$P10)<=($Q10-$P10)),"."," ") | BP10: =IF(AND((BP$6-$P10)>=0,(BP$6-$P10)<=($Q10-$P10)),"."," ") -> . | BQ10: =IF(AND((BQ$6-$P10)>=0,(BQ$6-$P10)<=($Q10-$P10)),"."," ") | BR10: =IF(AND((BR$6-$P10)>=0,(BR$6-$P10)<=($Q10-$P10)),"."," ") | BS10: =IF(AND((BS$6-$P10)>=0,(BS$6-$P10)<=($Q10-$P10)),"."," ") | BT10: =IF(AND((BT$6-$P10)>=0,(BT$6-$P10)<=($Q10-$P10)),"."," ") | BU10: =IF(AND((BU$6-$P10)>=0,(BU$6-$P10)<=($Q10-$P10)),"."," ") | ... CR10: =IF(AND((CR$6-$P10)>=0,(CR$6-$P10)<=($Q10-$P10)),"."," ")
A11: =VLOOKUP(L11,Ubicacion!A:K,2,FALSE) -> LI3BR | B11: =VLOOKUP(L11,Ubicacion!A:K,3,FALSE) -> LI3BC11 | C11: =VLOOKUP(L11,Ubicacion!A:K,4,FALSE) -> LIMA | D11: =VLOOKUP(L11,Ubicacion!A:K,5,FALSE) -> SAN JUAN DE MIRAFLORES 2 | E11: =VLOOKUP(L11,Ubicacion!A:K,6,FALSE) -> Plaza | F11: =VLOOKUP(L11,Ubicacion!A:K,7,FALSE) -> 09:00 - 17:00 | G11: =VLOOKUP(L11,Ubicacion!A:K,8,FALSE) -> TUESDAY | H11: =VLOOKUP(L11,Ubicacion!A:K,9,FALSE) -> 1 | I11: =VLOOKUP(L11,Ubicacion!A:K,10,FALSE) -> -12.132079 | J11: =VLOOKUP(L11,Ubicacion!A:K,11,FALSE) -> -76.954881 | K11: =P11&O11 -> 46146Grupo 1 | L11: CP05 | M11: 1 | N11: AD | O11: Grupo 1 | P11: 46146 | Q11: =P11+M11-1 -> 46146 | R11: =IF($A$1<Q11,"On-time",IF(AND(Q11<=$A$1,BJ11="OK"),"OK","NO OK")) -> NO OK | S11: =(UPPER(TEXT(P11,"dddd"))) -> MONDAY | T11: =VLOOKUP(L11,Ubicacion!A:AE,13,FALSE) -> 15 | U11: =VLOOKUP(L11,Ubicacion!A:AE,14,FALSE) -> 2 | V11: =VLOOKUP(L11,Ubicacion!A:AE,15,FALSE) -> 2 | W11: =VLOOKUP(L11,Ubicacion!A:AE,16,FALSE) -> 13 | X11: =VLOOKUP(L11,Ubicacion!A:AE,17,FALSE) -> 4 | Y11: =VLOOKUP(L11,Ubicacion!A:AE,18,FALSE) -> 4 | Z11: =VLOOKUP(L11,Ubicacion!A:AE,19,FALSE) -> 0 | AA11: =VLOOKUP(L11,Ubicacion!A:AE,20,FALSE) -> 0 | AB11: =VLOOKUP(L11,Ubicacion!A:AE,21,FALSE) -> 0 | AC11: =VLOOKUP(L11,Ubicacion!A:AE,22,FALSE) -> 2 | AD11: =VLOOKUP(L11,Ubicacion!A:AE,23,FALSE) -> 0 | AE11: =VLOOKUP(L11,Ubicacion!A:AE,24,FALSE) -> 0 | AF11: =VLOOKUP(L11,Ubicacion!A:AE,25,FALSE) -> 0 | AG11: =VLOOKUP(L11,Ubicacion!A:AE,26,FALSE) -> 2 | AH11: =VLOOKUP(L11,Ubicacion!A:AE,27,FALSE) -> 2 | AI11: =VLOOKUP(L11,Ubicacion!A:AE,28,FALSE) -> 5 | AJ11: =VLOOKUP(L11,Ubicacion!A:AE,29,FALSE) -> 3 | AK11: =VLOOKUP(L11,Ubicacion!A:AE,30,FALSE) -> 1 | AL11: =VLOOKUP(L11,Ubicacion!A:AE,31,FALSE) -> 1 | AM11: =IF(T11=0,"100%",AV11/T11) -> 0.66666667 | AN11: =IF(U11=0,"100%",AW11/U11) -> 0.5 | AO11: =IF(V11=0,"100%",AX11/V11) -> 1 | AP11: =IF(W11=0,"100%",AY11/W11) -> 0.15384615 | AQ11: =IF(X11=0,"100%",AZ11/X11) -> 0.5 | AR11: =IF(Y11=0,"100%",BA11/Y11) -> 0.25 | AS11: =IF(Z11=0,"100%",BB11/Z11) -> 100% | AT11: =IF(AA11=0,"100%",BC11/AA11) -> 100% | AU11: =IF(AB11=0,"100%",BD11/AB11) -> 100% | AV11: 10 | AW11: 1 | AX11: 2 | AY11: 2 | AZ11: 2 | BA11: 1 | BB11: 2 | BC11: 1 | BD11: 1 | BE11: NO OK | BF11: NO OK | BG11: OK | BH11: OK | BI11: OK | BJ11: NO OK | BN11: =IF(AND((BN$6-$P11)>=0,(BN$6-$P11)<=($Q11-$P11)),"."," ") | BO11: =IF(AND((BO$6-$P11)>=0,(BO$6-$P11)<=($Q11-$P11)),"."," ") | BP11: =IF(AND((BP$6-$P11)>=0,(BP$6-$P11)<=($Q11-$P11)),"."," ") | BQ11: =IF(AND((BQ$6-$P11)>=0,(BQ$6-$P11)<=($Q11-$P11)),"."," ") -> . | BR11: =IF(AND((BR$6-$P11)>=0,(BR$6-$P11)<=($Q11-$P11)),"."," ") | BS11: =IF(AND((BS$6-$P11)>=0,(BS$6-$P11)<=($Q11-$P11)),"."," ") | BT11: =IF(AND((BT$6-$P11)>=0,(BT$6-$P11)<=($Q11-$P11)),"."," ") | BU11: =IF(AND((BU$6-$P11)>=0,(BU$6-$P11)<=($Q11-$P11)),"."," ") | ... CR11: =IF(AND((CR$6-$P11)>=0,(CR$6-$P11)<=($Q11-$P11)),"."," ")
A12: =VLOOKUP(L12,Ubicacion!A:K,2,FALSE) -> LI3BR | B12: =VLOOKUP(L12,Ubicacion!A:K,3,FALSE) -> LI3BC06 | C12: =VLOOKUP(L12,Ubicacion!A:K,4,FALSE) -> LIMA | D12: =VLOOKUP(L12,Ubicacion!A:K,5,FALSE) -> SURCO | E12: =VLOOKUP(L12,Ubicacion!A:K,6,FALSE) -> Grifo | F12: =VLOOKUP(L12,Ubicacion!A:K,7,FALSE) -> 09:00 - 16:00 | G12: =VLOOKUP(L12,Ubicacion!A:K,8,FALSE) -> WEDNESDAY | H12: =VLOOKUP(L12,Ubicacion!A:K,9,FALSE) -> 1 | I12: =VLOOKUP(L12,Ubicacion!A:K,10,FALSE) -> -12.128573 | J12: =VLOOKUP(L12,Ubicacion!A:K,11,FALSE) -> -76.997765 | K12: =P12&O12 -> 46147Grupo 1 | L12: CP06 | M12: 1 | N12: PR A | O12: Grupo 1 | P12: 46147 | Q12: =P12+M12-1 -> 46147 | R12: =IF($A$1<Q12,"On-time",IF(AND(Q12<=$A$1,BJ12="OK"),"OK","NO OK")) -> NO OK | S12: =(UPPER(TEXT(P12,"dddd"))) -> TUESDAY | T12: =VLOOKUP(L12,Ubicacion!A:AE,13,FALSE) -> 15 | U12: =VLOOKUP(L12,Ubicacion!A:AE,14,FALSE) -> 2 | V12: =VLOOKUP(L12,Ubicacion!A:AE,15,FALSE) -> 2 | W12: =VLOOKUP(L12,Ubicacion!A:AE,16,FALSE) -> 13 | X12: =VLOOKUP(L12,Ubicacion!A:AE,17,FALSE) -> 4 | Y12: =VLOOKUP(L12,Ubicacion!A:AE,18,FALSE) -> 4 | Z12: =VLOOKUP(L12,Ubicacion!A:AE,19,FALSE) -> 0 | AA12: =VLOOKUP(L12,Ubicacion!A:AE,20,FALSE) -> 0 | AB12: =VLOOKUP(L12,Ubicacion!A:AE,21,FALSE) -> 0 | AC12: =VLOOKUP(L12,Ubicacion!A:AE,22,FALSE) -> 2 | AD12: =VLOOKUP(L12,Ubicacion!A:AE,23,FALSE) -> 0 | AE12: =VLOOKUP(L12,Ubicacion!A:AE,24,FALSE) -> 0 | AF12: =VLOOKUP(L12,Ubicacion!A:AE,25,FALSE) -> 0 | AG12: =VLOOKUP(L12,Ubicacion!A:AE,26,FALSE) -> 2 | AH12: =VLOOKUP(L12,Ubicacion!A:AE,27,FALSE) -> 2 | AI12: =VLOOKUP(L12,Ubicacion!A:AE,28,FALSE) -> 5 | AJ12: =VLOOKUP(L12,Ubicacion!A:AE,29,FALSE) -> 3 | AK12: =VLOOKUP(L12,Ubicacion!A:AE,30,FALSE) -> 1 | AL12: =VLOOKUP(L12,Ubicacion!A:AE,31,FALSE) -> 1 | AM12: =IF(T12=0,"100%",AV12/T12) -> 0.66666667 | AN12: =IF(U12=0,"100%",AW12/U12) -> 0.5 | AO12: =IF(V12=0,"100%",AX12/V12) -> 1 | AP12: =IF(W12=0,"100%",AY12/W12) -> 0.15384615 | AQ12: =IF(X12=0,"100%",AZ12/X12) -> 0.5 | AR12: =IF(Y12=0,"100%",BA12/Y12) -> 0.25 | AS12: =IF(Z12=0,"100%",BB12/Z12) -> 100% | AT12: =IF(AA12=0,"100%",BC12/AA12) -> 100% | AU12: =IF(AB12=0,"100%",BD12/AB12) -> 100% | AV12: 10 | AW12: 1 | AX12: 2 | AY12: 2 | AZ12: 2 | BA12: 1 | BB12: 2 | BC12: 1 | BD12: 1 | BE12: NO OK | BF12: NO OK | BG12: OK | BH12: OK | BI12: OK | BJ12: NO OK | BN12: =IF(AND((BN$6-$P12)>=0,(BN$6-$P12)<=($Q12-$P12)),"."," ") | BO12: =IF(AND((BO$6-$P12)>=0,(BO$6-$P12)<=($Q12-$P12)),"."," ") | BP12: =IF(AND((BP$6-$P12)>=0,(BP$6-$P12)<=($Q12-$P12)),"."," ") | BQ12: =IF(AND((BQ$6-$P12)>=0,(BQ$6-$P12)<=($Q12-$P12)),"."," ") | BR12: =IF(AND((BR$6-$P12)>=0,(BR$6-$P12)<=($Q12-$P12)),"."," ") -> . | BS12: =IF(AND((BS$6-$P12)>=0,(BS$6-$P12)<=($Q12-$P12)),"."," ") | BT12: =IF(AND((BT$6-$P12)>=0,(BT$6-$P12)<=($Q12-$P12)),"."," ") | BU12: =IF(AND((BU$6-$P12)>=0,(BU$6-$P12)<=($Q12-$P12)),"."," ") | ... CR12: =IF(AND((CR$6-$P12)>=0,(CR$6-$P12)<=($Q12-$P12)),"."," ")
A13: =VLOOKUP(L13,Ubicacion!A:K,2,FALSE) -> LI3BR | B13: =VLOOKUP(L13,Ubicacion!A:K,3,FALSE) -> LI3BC06 | C13: =VLOOKUP(L13,Ubicacion!A:K,4,FALSE) -> LIMA | D13: =VLOOKUP(L13,Ubicacion!A:K,5,FALSE) -> SURCO | E13: =VLOOKUP(L13,Ubicacion!A:K,6,FALSE) -> Mercado | F13: =VLOOKUP(L13,Ubicacion!A:K,7,FALSE) -> 8:00 - 16:00 | G13: =VLOOKUP(L13,Ubicacion!A:K,8,FALSE) -> THURSDAY | H13: =VLOOKUP(L13,Ubicacion!A:K,9,FALSE) -> 1 | I13: =VLOOKUP(L13,Ubicacion!A:K,10,FALSE) -> -12.122129 | J13: =VLOOKUP(L13,Ubicacion!A:K,11,FALSE) -> -76.992532 | K13: =P13&O13 -> 46148Grupo 1 | L13: CP07 | M13: 1 | N13: PR B | O13: Grupo 1 | P13: 46148 | Q13: =P13+M13-1 -> 46148 | R13: =IF($A$1<Q13,"On-time",IF(AND(Q13<=$A$1,BJ13="OK"),"OK","NO OK")) -> OK | S13: =(UPPER(TEXT(P13,"dddd"))) -> WEDNESDAY | T13: =VLOOKUP(L13,Ubicacion!A:AE,13,FALSE) -> 15 | U13: =VLOOKUP(L13,Ubicacion!A:AE,14,FALSE) -> 2 | V13: =VLOOKUP(L13,Ubicacion!A:AE,15,FALSE) -> 2 | W13: =VLOOKUP(L13,Ubicacion!A:AE,16,FALSE) -> 13 | X13: =VLOOKUP(L13,Ubicacion!A:AE,17,FALSE) -> 4 | Y13: =VLOOKUP(L13,Ubicacion!A:AE,18,FALSE) -> 4 | Z13: =VLOOKUP(L13,Ubicacion!A:AE,19,FALSE) -> 0 | AA13: =VLOOKUP(L13,Ubicacion!A:AE,20,FALSE) -> 0 | AB13: =VLOOKUP(L13,Ubicacion!A:AE,21,FALSE) -> 0 | AC13: =VLOOKUP(L13,Ubicacion!A:AE,22,FALSE) -> 2 | AD13: =VLOOKUP(L13,Ubicacion!A:AE,23,FALSE) -> 0 | AE13: =VLOOKUP(L13,Ubicacion!A:AE,24,FALSE) -> 0 | AF13: =VLOOKUP(L13,Ubicacion!A:AE,25,FALSE) -> 0 | AG13: =VLOOKUP(L13,Ubicacion!A:AE,26,FALSE) -> 2 | AH13: =VLOOKUP(L13,Ubicacion!A:AE,27,FALSE) -> 2 | AI13: =VLOOKUP(L13,Ubicacion!A:AE,28,FALSE) -> 5 | AJ13: =VLOOKUP(L13,Ubicacion!A:AE,29,FALSE) -> 3 | AK13: =VLOOKUP(L13,Ubicacion!A:AE,30,FALSE) -> 1 | AL13: =VLOOKUP(L13,Ubicacion!A:AE,31,FALSE) -> 1 | AM13: =IF(T13=0,"100%",AV13/T13) -> 0.66666667 | AN13: =IF(U13=0,"100%",AW13/U13) -> 0.5 | AO13: =IF(V13=0,"100%",AX13/V13) -> 1 | AP13: =IF(W13=0,"100%",AY13/W13) -> 0.15384615 | AQ13: =IF(X13=0,"100%",AZ13/X13) -> 0.5 | AR13: =IF(Y13=0,"100%",BA13/Y13) -> 0.25 | AS13: =IF(Z13=0,"100%",BB13/Z13) -> 100% | AT13: =IF(AA13=0,"100%",BC13/AA13) -> 100% | AU13: =IF(AB13=0,"100%",BD13/AB13) -> 100% | AV13: 10 | AW13: 1 | AX13: 2 | AY13: 2 | AZ13: 2 | BA13: 1 | BB13: 2 | BC13: 1 | BD13: 1 | BE13: NO OK | BF13: NO OK | BG13: OK | BH13: OK | BI13: OK | BJ13: OK | BN13: =IF(AND((BN$6-$P13)>=0,(BN$6-$P13)<=($Q13-$P13)),"."," ") | BO13: =IF(AND((BO$6-$P13)>=0,(BO$6-$P13)<=($Q13-$P13)),"."," ") | BP13: =IF(AND((BP$6-$P13)>=0,(BP$6-$P13)<=($Q13-$P13)),"."," ") | BQ13: =IF(AND((BQ$6-$P13)>=0,(BQ$6-$P13)<=($Q13-$P13)),"."," ") | BR13: =IF(AND((BR$6-$P13)>=0,(BR$6-$P13)<=($Q13-$P13)),"."," ") | BS13: =IF(AND((BS$6-$P13)>=0,(BS$6-$P13)<=($Q13-$P13)),"."," ") -> . | BT13: =IF(AND((BT$6-$P13)>=0,(BT$6-$P13)<=($Q13-$P13)),"."," ") | BU13: =IF(AND((BU$6-$P13)>=0,(BU$6-$P13)<=($Q13-$P13)),"."," ") | ... CR13: =IF(AND((CR$6-$P13)>=0,(CR$6-$P13)<=($Q13-$P13)),"."," ")
A14: =VLOOKUP(L14,Ubicacion!A:K,2,FALSE) -> LI3BR | B14: =VLOOKUP(L14,Ubicacion!A:K,3,FALSE) -> LI3BC03 | C14: =VLOOKUP(L14,Ubicacion!A:K,4,FALSE) -> LIMA | D14: =VLOOKUP(L14,Ubicacion!A:K,5,FALSE) -> CHORRILLOS | E14: =VLOOKUP(L14,Ubicacion!A:K,6,FALSE) -> Rural | F14: =VLOOKUP(L14,Ubicacion!A:K,7,FALSE) -> 8:00 - 13:00 | G14: =VLOOKUP(L14,Ubicacion!A:K,8,FALSE) -> FRIDAY | H14: =VLOOKUP(L14,Ubicacion!A:K,9,FALSE) -> 1 | I14: =VLOOKUP(L14,Ubicacion!A:K,10,FALSE) -> -12.202221 | J14: =VLOOKUP(L14,Ubicacion!A:K,11,FALSE) -> -77.020581 | K14: =P14&O14 -> 46149Grupo 1 | L14: CP08 | M14: 1 | N14: AF | O14: Grupo 1 | P14: 46149 | Q14: =P14+M14-1 -> 46149 | R14: =IF($A$1<Q14,"On-time",IF(AND(Q14<=$A$1,BJ14="OK"),"OK","NO OK")) -> OK | S14: =(UPPER(TEXT(P14,"dddd"))) -> THURSDAY | T14: =VLOOKUP(L14,Ubicacion!A:AE,13,FALSE) -> 15 | U14: =VLOOKUP(L14,Ubicacion!A:AE,14,FALSE) -> 2 | V14: =VLOOKUP(L14,Ubicacion!A:AE,15,FALSE) -> 2 | W14: =VLOOKUP(L14,Ubicacion!A:AE,16,FALSE) -> 13 | X14: =VLOOKUP(L14,Ubicacion!A:AE,17,FALSE) -> 4 | Y14: =VLOOKUP(L14,Ubicacion!A:AE,18,FALSE) -> 4 | Z14: =VLOOKUP(L14,Ubicacion!A:AE,19,FALSE) -> 0 | AA14: =VLOOKUP(L14,Ubicacion!A:AE,20,FALSE) -> 0 | AB14: =VLOOKUP(L14,Ubicacion!A:AE,21,FALSE) -> 0 | AC14: =VLOOKUP(L14,Ubicacion!A:AE,22,FALSE) -> 2 | AD14: =VLOOKUP(L14,Ubicacion!A:AE,23,FALSE) -> 0 | AE14: =VLOOKUP(L14,Ubicacion!A:AE,24,FALSE) -> 0 | AF14: =VLOOKUP(L14,Ubicacion!A:AE,25,FALSE) -> 0 | AG14: =VLOOKUP(L14,Ubicacion!A:AE,26,FALSE) -> 2 | AH14: =VLOOKUP(L14,Ubicacion!A:AE,27,FALSE) -> 2 | AI14: =VLOOKUP(L14,Ubicacion!A:AE,28,FALSE) -> 5 | AJ14: =VLOOKUP(L14,Ubicacion!A:AE,29,FALSE) -> 3 | AK14: =VLOOKUP(L14,Ubicacion!A:AE,30,FALSE) -> 1 | AL14: =VLOOKUP(L14,Ubicacion!A:AE,31,FALSE) -> 1 | AM14: =IF(T14=0,"100%",AV14/T14) -> 0.66666667 | AN14: =IF(U14=0,"100%",AW14/U14) -> 0.5 | AO14: =IF(V14=0,"100%",AX14/V14) -> 1 | AP14: =IF(W14=0,"100%",AY14/W14) -> 0.15384615 | AQ14: =IF(X14=0,"100%",AZ14/X14) -> 0.5 | AR14: =IF(Y14=0,"100%",BA14/Y14) -> 0.25 | AS14: =IF(Z14=0,"100%",BB14/Z14) -> 100% | AT14: =IF(AA14=0,"100%",BC14/AA14) -> 100% | AU14: =IF(AB14=0,"100%",BD14/AB14) -> 100% | AV14: 10 | AW14: 1 | AX14: 2 | AY14: 2 | AZ14: 2 | BA14: 1 | BB14: 2 | BC14: 1 | BD14: 1 | BE14: NO OK | BF14: NO OK | BG14: OK | BH14: OK | BI14: OK | BJ14: OK | BN14: =IF(AND((BN$6-$P14)>=0,(BN$6-$P14)<=($Q14-$P14)),"."," ") | BO14: =IF(AND((BO$6-$P14)>=0,(BO$6-$P14)<=($Q14-$P14)),"."," ") | BP14: =IF(AND((BP$6-$P14)>=0,(BP$6-$P14)<=($Q14-$P14)),"."," ") | BQ14: =IF(AND((BQ$6-$P14)>=0,(BQ$6-$P14)<=($Q14-$P14)),"."," ") | BR14: =IF(AND((BR$6-$P14)>=0,(BR$6-$P14)<=($Q14-$P14)),"."," ") | BS14: =IF(AND((BS$6-$P14)>=0,(BS$6-$P14)<=($Q14-$P14)),"."," ") | BT14: =IF(AND((BT$6-$P14)>=0,(BT$6-$P14)<=($Q14-$P14)),"."," ") -> . | BU14: =IF(AND((BU$6-$P14)>=0,(BU$6-$P14)<=($Q14-$P14)),"."," ") | ... CR14: =IF(AND((CR$6-$P14)>=0,(CR$6-$P14)<=($Q14-$P14)),"."," ")
A15: =VLOOKUP(L15,Ubicacion!A:K,2,FALSE) -> LI3BR | B15: =VLOOKUP(L15,Ubicacion!A:K,3,FALSE) -> LI3BC07 | C15: =VLOOKUP(L15,Ubicacion!A:K,4,FALSE) -> LIMA | D15: =VLOOKUP(L15,Ubicacion!A:K,5,FALSE) -> SAN JUAN DE MIRAFLORES 1 | E15: =VLOOKUP(L15,Ubicacion!A:K,6,FALSE) -> Pilot Mercado | F15: =VLOOKUP(L15,Ubicacion!A:K,7,FALSE) -> 09:00 - 17:00 | G15: =VLOOKUP(L15,Ubicacion!A:K,8,FALSE) -> SATURDAY | H15: =VLOOKUP(L15,Ubicacion!A:K,9,FALSE) -> 1 | I15: =VLOOKUP(L15,Ubicacion!A:K,10,FALSE) -> -12.163083 | J15: =VLOOKUP(L15,Ubicacion!A:K,11,FALSE) -> -76.965185 | K15: =P15&O15 -> 46150Grupo 1 | L15: CP09 | M15: 1 | N15: AF | O15: Grupo 1 | P15: 46150 | Q15: =P15+M15-1 -> 46150 | R15: =IF($A$1<Q15,"On-time",IF(AND(Q15<=$A$1,BJ15="OK"),"OK","NO OK")) -> OK | S15: =(UPPER(TEXT(P15,"dddd"))) -> FRIDAY | T15: =VLOOKUP(L15,Ubicacion!A:AE,13,FALSE) -> 15 | U15: =VLOOKUP(L15,Ubicacion!A:AE,14,FALSE) -> 2 | V15: =VLOOKUP(L15,Ubicacion!A:AE,15,FALSE) -> 2 | W15: =VLOOKUP(L15,Ubicacion!A:AE,16,FALSE) -> 13 | X15: =VLOOKUP(L15,Ubicacion!A:AE,17,FALSE) -> 4 | Y15: =VLOOKUP(L15,Ubicacion!A:AE,18,FALSE) -> 4 | Z15: =VLOOKUP(L15,Ubicacion!A:AE,19,FALSE) -> 0 | AA15: =VLOOKUP(L15,Ubicacion!A:AE,20,FALSE) -> 0 | AB15: =VLOOKUP(L15,Ubicacion!A:AE,21,FALSE) -> 0 | AC15: =VLOOKUP(L15,Ubicacion!A:AE,22,FALSE) -> 2 | AD15: =VLOOKUP(L15,Ubicacion!A:AE,23,FALSE) -> 0 | AE15: =VLOOKUP(L15,Ubicacion!A:AE,24,FALSE) -> 0 | AF15: =VLOOKUP(L15,Ubicacion!A:AE,25,FALSE) -> 0 | AG15: =VLOOKUP(L15,Ubicacion!A:AE,26,FALSE) -> 2 | AH15: =VLOOKUP(L15,Ubicacion!A:AE,27,FALSE) -> 2 | AI15: =VLOOKUP(L15,Ubicacion!A:AE,28,FALSE) -> 5 | AJ15: =VLOOKUP(L15,Ubicacion!A:AE,29,FALSE) -> 3 | AK15: =VLOOKUP(L15,Ubicacion!A:AE,30,FALSE) -> 1 | AL15: =VLOOKUP(L15,Ubicacion!A:AE,31,FALSE) -> 1 | AM15: =IF(T15=0,"100%",AV15/T15) -> 0.66666667 | AN15: =IF(U15=0,"100%",AW15/U15) -> 0.5 | AO15: =IF(V15=0,"100%",AX15/V15) -> 1 | AP15: =IF(W15=0,"100%",AY15/W15) -> 0.15384615 | AQ15: =IF(X15=0,"100%",AZ15/X15) -> 0.5 | AR15: =IF(Y15=0,"100%",BA15/Y15) -> 0.25 | AS15: =IF(Z15=0,"100%",BB15/Z15) -> 100% | AT15: =IF(AA15=0,"100%",BC15/AA15) -> 100% | AU15: =IF(AB15=0,"100%",BD15/AB15) -> 100% | AV15: 10 | AW15: 1 | AX15: 2 | AY15: 2 | AZ15: 2 | BA15: 1 | BB15: 2 | BC15: 1 | BD15: 1 | BE15: NO OK | BF15: NO OK | BG15: OK | BH15: OK | BI15: OK | BJ15: OK | BN15: =IF(AND((BN$6-$P15)>=0,(BN$6-$P15)<=($Q15-$P15)),"."," ") | BO15: =IF(AND((BO$6-$P15)>=0,(BO$6-$P15)<=($Q15-$P15)),"."," ") | BP15: =IF(AND((BP$6-$P15)>=0,(BP$6-$P15)<=($Q15-$P15)),"."," ") | BQ15: =IF(AND((BQ$6-$P15)>=0,(BQ$6-$P15)<=($Q15-$P15)),"."," ") | BR15: =IF(AND((BR$6-$P15)>=0,(BR$6-$P15)<=($Q15-$P15)),"."," ") | BS15: =IF(AND((BS$6-$P15)>=0,(BS$6-$P15)<=($Q15-$P15)),"."," ") | BT15: =IF(AND((BT$6-$P15)>=0,(BT$6-$P15)<=($Q15-$P15)),"."," ") | BU15: =IF(AND((BU$6-$P15)>=0,(BU$6-$P15)<=($Q15-$P15)),"."," ") -> . | ... CR15: =IF(AND((CR$6-$P15)>=0,(CR$6-$P15)<=($Q15-$P15)),"."," ")
A16: =VLOOKUP(L16,Ubicacion!A:K,2,FALSE) -> LI3BR | B16: =VLOOKUP(L16,Ubicacion!A:K,3,FALSE) -> LI3BC07 | C16: =VLOOKUP(L16,Ubicacion!A:K,4,FALSE) -> LIMA | D16: =VLOOKUP(L16,Ubicacion!A:K,5,FALSE) -> SAN JUAN DE MIRAFLORES 1 | E16: =VLOOKUP(L16,Ubicacion!A:K,6,FALSE) -> Rural | F16: =VLOOKUP(L16,Ubicacion!A:K,7,FALSE) -> 8:00 - 12:00 | G16: =VLOOKUP(L16,Ubicacion!A:K,8,FALSE) -> SUNDAY | H16: =VLOOKUP(L16,Ubicacion!A:K,9,FALSE) -> 1 | I16: =VLOOKUP(L16,Ubicacion!A:K,10,FALSE) -> -12.191882 | J16: =VLOOKUP(L16,Ubicacion!A:K,11,FALSE) -> -76.956277 | K16: =P16&O16 -> 46151Grupo 1 | L16: CP10 | M16: 1 | N16: AF | O16: Grupo 1 | P16: 46151 | Q16: =P16+M16-1 -> 46151 | R16: =IF($A$1<Q16,"On-time",IF(AND(Q16<=$A$1,BJ16="OK"),"OK","NO OK")) -> OK | S16: =(UPPER(TEXT(P16,"dddd"))) -> SATURDAY | T16: =VLOOKUP(L16,Ubicacion!A:AE,13,FALSE) -> 15 | U16: =VLOOKUP(L16,Ubicacion!A:AE,14,FALSE) -> 2 | V16: =VLOOKUP(L16,Ubicacion!A:AE,15,FALSE) -> 2 | W16: =VLOOKUP(L16,Ubicacion!A:AE,16,FALSE) -> 13 | X16: =VLOOKUP(L16,Ubicacion!A:AE,17,FALSE) -> 4 | Y16: =VLOOKUP(L16,Ubicacion!A:AE,18,FALSE) -> 4 | Z16: =VLOOKUP(L16,Ubicacion!A:AE,19,FALSE) -> 0 | AA16: =VLOOKUP(L16,Ubicacion!A:AE,20,FALSE) -> 0 | AB16: =VLOOKUP(L16,Ubicacion!A:AE,21,FALSE) -> 0 | AC16: =VLOOKUP(L16,Ubicacion!A:AE,22,FALSE) -> 2 | AD16: =VLOOKUP(L16,Ubicacion!A:AE,23,FALSE) -> 0 | AE16: =VLOOKUP(L16,Ubicacion!A:AE,24,FALSE) -> 0 | AF16: =VLOOKUP(L16,Ubicacion!A:AE,25,FALSE) -> 0 | AG16: =VLOOKUP(L16,Ubicacion!A:AE,26,FALSE) -> 2 | AH16: =VLOOKUP(L16,Ubicacion!A:AE,27,FALSE) -> 2 | AI16: =VLOOKUP(L16,Ubicacion!A:AE,28,FALSE) -> 5 | AJ16: =VLOOKUP(L16,Ubicacion!A:AE,29,FALSE) -> 3 | AK16: =VLOOKUP(L16,Ubicacion!A:AE,30,FALSE) -> 1 | AL16: =VLOOKUP(L16,Ubicacion!A:AE,31,FALSE) -> 1 | AM16: =IF(T16=0,"100%",AV16/T16) -> 0.66666667 | AN16: =IF(U16=0,"100%",AW16/U16) -> 0.5 | AO16: =IF(V16=0,"100%",AX16/V16) -> 1 | AP16: =IF(W16=0,"100%",AY16/W16) -> 0.15384615 | AQ16: =IF(X16=0,"100%",AZ16/X16) -> 0.5 | AR16: =IF(Y16=0,"100%",BA16/Y16) -> 0.25 | AS16: =IF(Z16=0,"100%",BB16/Z16) -> 100% | AT16: =IF(AA16=0,"100%",BC16/AA16) -> 100% | AU16: =IF(AB16=0,"100%",BD16/AB16) -> 100% | AV16: 10 | AW16: 1 | AX16: 2 | AY16: 2 | AZ16: 2 | BA16: 1 | BB16: 2 | BC16: 1 | BD16: 1 | BE16: NO OK | BF16: NO OK | BG16: OK | BH16: OK | BI16: OK | BJ16: OK | BN16: =IF(AND((BN$6-$P16)>=0,(BN$6-$P16)<=($Q16-$P16)),"."," ") | BO16: =IF(AND((BO$6-$P16)>=0,(BO$6-$P16)<=($Q16-$P16)),"."," ") | BP16: =IF(AND((BP$6-$P16)>=0,(BP$6-$P16)<=($Q16-$P16)),"."," ") | BQ16: =IF(AND((BQ$6-$P16)>=0,(BQ$6-$P16)<=($Q16-$P16)),"."," ") | BR16: =IF(AND((BR$6-$P16)>=0,(BR$6-$P16)<=($Q16-$P16)),"."," ") | BS16: =IF(AND((BS$6-$P16)>=0,(BS$6-$P16)<=($Q16-$P16)),"."," ") | BT16: =IF(AND((BT$6-$P16)>=0,(BT$6-$P16)<=($Q16-$P16)),"."," ") | BU16: =IF(AND((BU$6-$P16)>=0,(BU$6-$P16)<=($Q16-$P16)),"."," ") | ... CR16: =IF(AND((CR$6-$P16)>=0,(CR$6-$P16)<=($Q16-$P16)),"."," ")
A17: =VLOOKUP(L17,Ubicacion!A:K,2,FALSE) -> LI3BR | B17: =VLOOKUP(L17,Ubicacion!A:K,3,FALSE) -> LI3BC03 | C17: =VLOOKUP(L17,Ubicacion!A:K,4,FALSE) -> LIMA | D17: =VLOOKUP(L17,Ubicacion!A:K,5,FALSE) -> CHORRILLOS | E17: =VLOOKUP(L17,Ubicacion!A:K,6,FALSE) -> Rural | F17: =VLOOKUP(L17,Ubicacion!A:K,7,FALSE) -> 8:00 - 16:00 | G17: =VLOOKUP(L17,Ubicacion!A:K,8,FALSE) -> MONDAY | H17: =VLOOKUP(L17,Ubicacion!A:K,9,FALSE) -> 1 | I17: =VLOOKUP(L17,Ubicacion!A:K,10,FALSE) -> -12.168759 | J17: =VLOOKUP(L17,Ubicacion!A:K,11,FALSE) -> -77.02618 | K17: =P17&O17 -> 46152Grupo 1 | L17: CP11 | M17: 1 | N17: AF | O17: Grupo 1 | P17: 46152 | Q17: =P17+M17-1 -> 46152 | R17: =IF($A$1<Q17,"On-time",IF(AND(Q17<=$A$1,BJ17="OK"),"OK","NO OK")) -> OK | S17: =(UPPER(TEXT(P17,"dddd"))) -> SUNDAY | T17: =VLOOKUP(L17,Ubicacion!A:AE,13,FALSE) -> 15 | U17: =VLOOKUP(L17,Ubicacion!A:AE,14,FALSE) -> 2 | V17: =VLOOKUP(L17,Ubicacion!A:AE,15,FALSE) -> 2 | W17: =VLOOKUP(L17,Ubicacion!A:AE,16,FALSE) -> 13 | X17: =VLOOKUP(L17,Ubicacion!A:AE,17,FALSE) -> 4 | Y17: =VLOOKUP(L17,Ubicacion!A:AE,18,FALSE) -> 4 | Z17: =VLOOKUP(L17,Ubicacion!A:AE,19,FALSE) -> 0 | AA17: =VLOOKUP(L17,Ubicacion!A:AE,20,FALSE) -> 0 | AB17: =VLOOKUP(L17,Ubicacion!A:AE,21,FALSE) -> 0 | AC17: =VLOOKUP(L17,Ubicacion!A:AE,22,FALSE) -> 2 | AD17: =VLOOKUP(L17,Ubicacion!A:AE,23,FALSE) -> 0 | AE17: =VLOOKUP(L17,Ubicacion!A:AE,24,FALSE) -> 0 | AF17: =VLOOKUP(L17,Ubicacion!A:AE,25,FALSE) -> 0 | AG17: =VLOOKUP(L17,Ubicacion!A:AE,26,FALSE) -> 2 | AH17: =VLOOKUP(L17,Ubicacion!A:AE,27,FALSE) -> 2 | AI17: =VLOOKUP(L17,Ubicacion!A:AE,28,FALSE) -> 5 | AJ17: =VLOOKUP(L17,Ubicacion!A:AE,29,FALSE) -> 3 | AK17: =VLOOKUP(L17,Ubicacion!A:AE,30,FALSE) -> 1 | AL17: =VLOOKUP(L17,Ubicacion!A:AE,31,FALSE) -> 1 | AM17: =IF(T17=0,"100%",AV17/T17) -> 0.66666667 | AN17: =IF(U17=0,"100%",AW17/U17) -> 0.5 | AO17: =IF(V17=0,"100%",AX17/V17) -> 1 | AP17: =IF(W17=0,"100%",AY17/W17) -> 0.15384615 | AQ17: =IF(X17=0,"100%",AZ17/X17) -> 0.5 | AR17: =IF(Y17=0,"100%",BA17/Y17) -> 0.25 | AS17: =IF(Z17=0,"100%",BB17/Z17) -> 100% | AT17: =IF(AA17=0,"100%",BC17/AA17) -> 100% | AU17: =IF(AB17=0,"100%",BD17/AB17) -> 100% | AV17: 10 | AW17: 1 | AX17: 2 | AY17: 2 | AZ17: 2 | BA17: 1 | BB17: 2 | BC17: 1 | BD17: 1 | BE17: NO OK | BF17: NO OK | BG17: OK | BH17: OK | BI17: OK | BJ17: OK | BN17: =IF(AND((BN$6-$P17)>=0,(BN$6-$P17)<=($Q17-$P17)),"."," ") | BO17: =IF(AND((BO$6-$P17)>=0,(BO$6-$P17)<=($Q17-$P17)),"."," ") | BP17: =IF(AND((BP$6-$P17)>=0,(BP$6-$P17)<=($Q17-$P17)),"."," ") | BQ17: =IF(AND((BQ$6-$P17)>=0,(BQ$6-$P17)<=($Q17-$P17)),"."," ") | BR17: =IF(AND((BR$6-$P17)>=0,(BR$6-$P17)<=($Q17-$P17)),"."," ") | BS17: =IF(AND((BS$6-$P17)>=0,(BS$6-$P17)<=($Q17-$P17)),"."," ") | BT17: =IF(AND((BT$6-$P17)>=0,(BT$6-$P17)<=($Q17-$P17)),"."," ") | BU17: =IF(AND((BU$6-$P17)>=0,(BU$6-$P17)<=($Q17-$P17)),"."," ") | ... CR17: =IF(AND((CR$6-$P17)>=0,(CR$6-$P17)<=($Q17-$P17)),"."," ")
A18: =VLOOKUP(L18,Ubicacion!A:K,2,FALSE) -> LI3BR | B18: =VLOOKUP(L18,Ubicacion!A:K,3,FALSE) -> LI2BC13 | C18: =VLOOKUP(L18,Ubicacion!A:K,4,FALSE) -> LIMA | D18: =VLOOKUP(L18,Ubicacion!A:K,5,FALSE) -> SAN BORJA | E18: =VLOOKUP(L18,Ubicacion!A:K,6,FALSE) -> Rural | F18: =VLOOKUP(L18,Ubicacion!A:K,7,FALSE) -> 10:00 - 16:00 | G18: =VLOOKUP(L18,Ubicacion!A:K,8,FALSE) -> TUESDAY | H18: =VLOOKUP(L18,Ubicacion!A:K,9,FALSE) -> 1 | I18: =VLOOKUP(L18,Ubicacion!A:K,10,FALSE) -> -12.098804 | J18: =VLOOKUP(L18,Ubicacion!A:K,11,FALSE) -> -77.011131 | K18: =P18&O18 -> 46153Grupo 1 | L18: CP12 | M18: 1 | N18: AF | O18: Grupo 1 | P18: 46153 | Q18: =P18+M18-1 -> 46153 | R18: =IF($A$1<Q18,"On-time",IF(AND(Q18<=$A$1,BJ18="OK"),"OK","NO OK")) -> OK | S18: =(UPPER(TEXT(P18,"dddd"))) -> MONDAY | T18: =VLOOKUP(L18,Ubicacion!A:AE,13,FALSE) -> 15 | U18: =VLOOKUP(L18,Ubicacion!A:AE,14,FALSE) -> 2 | V18: =VLOOKUP(L18,Ubicacion!A:AE,15,FALSE) -> 2 | W18: =VLOOKUP(L18,Ubicacion!A:AE,16,FALSE) -> 13 | X18: =VLOOKUP(L18,Ubicacion!A:AE,17,FALSE) -> 4 | Y18: =VLOOKUP(L18,Ubicacion!A:AE,18,FALSE) -> 4 | Z18: =VLOOKUP(L18,Ubicacion!A:AE,19,FALSE) -> 0 | AA18: =VLOOKUP(L18,Ubicacion!A:AE,20,FALSE) -> 0 | AB18: =VLOOKUP(L18,Ubicacion!A:AE,21,FALSE) -> 0 | AC18: =VLOOKUP(L18,Ubicacion!A:AE,22,FALSE) -> 2 | AD18: =VLOOKUP(L18,Ubicacion!A:AE,23,FALSE) -> 0 | AE18: =VLOOKUP(L18,Ubicacion!A:AE,24,FALSE) -> 0 | AF18: =VLOOKUP(L18,Ubicacion!A:AE,25,FALSE) -> 0 | AG18: =VLOOKUP(L18,Ubicacion!A:AE,26,FALSE) -> 2 | AH18: =VLOOKUP(L18,Ubicacion!A:AE,27,FALSE) -> 2 | AI18: =VLOOKUP(L18,Ubicacion!A:AE,28,FALSE) -> 5 | AJ18: =VLOOKUP(L18,Ubicacion!A:AE,29,FALSE) -> 3 | AK18: =VLOOKUP(L18,Ubicacion!A:AE,30,FALSE) -> 1 | AL18: =VLOOKUP(L18,Ubicacion!A:AE,31,FALSE) -> 1 | AM18: =IF(T18=0,"100%",AV18/T18) -> 0.66666667 | AN18: =IF(U18=0,"100%",AW18/U18) -> 0.5 | AO18: =IF(V18=0,"100%",AX18/V18) -> 1 | AP18: =IF(W18=0,"100%",AY18/W18) -> 0.15384615 | AQ18: =IF(X18=0,"100%",AZ18/X18) -> 0.5 | AR18: =IF(Y18=0,"100%",BA18/Y18) -> 0.25 | AS18: =IF(Z18=0,"100%",BB18/Z18) -> 100% | AT18: =IF(AA18=0,"100%",BC18/AA18) -> 100% | AU18: =IF(AB18=0,"100%",BD18/AB18) -> 100% | AV18: 10 | AW18: 1 | AX18: 2 | AY18: 2 | AZ18: 2 | BA18: 1 | BB18: 2 | BC18: 1 | BD18: 1 | BE18: NO OK | BF18: NO OK | BG18: OK | BH18: OK | BI18: OK | BJ18: OK | BN18: =IF(AND((BN$6-$P18)>=0,(BN$6-$P18)<=($Q18-$P18)),"."," ") | BO18: =IF(AND((BO$6-$P18)>=0,(BO$6-$P18)<=($Q18-$P18)),"."," ") | BP18: =IF(AND((BP$6-$P18)>=0,(BP$6-$P18)<=($Q18-$P18)),"."," ") | BQ18: =IF(AND((BQ$6-$P18)>=0,(BQ$6-$P18)<=($Q18-$P18)),"."," ") | BR18: =IF(AND((BR$6-$P18)>=0,(BR$6-$P18)<=($Q18-$P18)),"."," ") | BS18: =IF(AND((BS$6-$P18)>=0,(BS$6-$P18)<=($Q18-$P18)),"."," ") | BT18: =IF(AND((BT$6-$P18)>=0,(BT$6-$P18)<=($Q18-$P18)),"."," ") | BU18: =IF(AND((BU$6-$P18)>=0,(BU$6-$P18)<=($Q18-$P18)),"."," ") | ... CR18: =IF(AND((CR$6-$P18)>=0,(CR$6-$P18)<=($Q18-$P18)),"."," ")
A19: =VLOOKUP(L19,Ubicacion!A:K,2,FALSE) -> LI3BR | B19: =VLOOKUP(L19,Ubicacion!A:K,3,FALSE) -> LI3BC03 | C19: =VLOOKUP(L19,Ubicacion!A:K,4,FALSE) -> LIMA | D19: =VLOOKUP(L19,Ubicacion!A:K,5,FALSE) -> CHORRILLOS | E19: =VLOOKUP(L19,Ubicacion!A:K,6,FALSE) -> Rural | F19: =VLOOKUP(L19,Ubicacion!A:K,7,FALSE) -> 7:00 - 19:00 | G19: =VLOOKUP(L19,Ubicacion!A:K,8,FALSE) -> WEDNESDAY | H19: =VLOOKUP(L19,Ubicacion!A:K,9,FALSE) -> 1 | I19: =VLOOKUP(L19,Ubicacion!A:K,10,FALSE) -> -12.169822 | J19: =VLOOKUP(L19,Ubicacion!A:K,11,FALSE) -> -77.023673 | K19: =P19&O19 -> 46154Grupo 1 | L19: CP13 | M19: 1 | N19: AF | O19: Grupo 1 | P19: 46154 | Q19: =P19+M19-1 -> 46154 | R19: =IF($A$1<Q19,"On-time",IF(AND(Q19<=$A$1,BJ19="OK"),"OK","NO OK")) -> OK | S19: =(UPPER(TEXT(P19,"dddd"))) -> TUESDAY | T19: =VLOOKUP(L19,Ubicacion!A:AE,13,FALSE) -> 15 | U19: =VLOOKUP(L19,Ubicacion!A:AE,14,FALSE) -> 2 | V19: =VLOOKUP(L19,Ubicacion!A:AE,15,FALSE) -> 2 | W19: =VLOOKUP(L19,Ubicacion!A:AE,16,FALSE) -> 13 | X19: =VLOOKUP(L19,Ubicacion!A:AE,17,FALSE) -> 4 | Y19: =VLOOKUP(L19,Ubicacion!A:AE,18,FALSE) -> 4 | Z19: =VLOOKUP(L19,Ubicacion!A:AE,19,FALSE) -> 0 | AA19: =VLOOKUP(L19,Ubicacion!A:AE,20,FALSE) -> 0 | AB19: =VLOOKUP(L19,Ubicacion!A:AE,21,FALSE) -> 0 | AC19: =VLOOKUP(L19,Ubicacion!A:AE,22,FALSE) -> 2 | AD19: =VLOOKUP(L19,Ubicacion!A:AE,23,FALSE) -> 0 | AE19: =VLOOKUP(L19,Ubicacion!A:AE,24,FALSE) -> 0 | AF19: =VLOOKUP(L19,Ubicacion!A:AE,25,FALSE) -> 0 | AG19: =VLOOKUP(L19,Ubicacion!A:AE,26,FALSE) -> 2 | AH19: =VLOOKUP(L19,Ubicacion!A:AE,27,FALSE) -> 2 | AI19: =VLOOKUP(L19,Ubicacion!A:AE,28,FALSE) -> 5 | AJ19: =VLOOKUP(L19,Ubicacion!A:AE,29,FALSE) -> 3 | AK19: =VLOOKUP(L19,Ubicacion!A:AE,30,FALSE) -> 1 | AL19: =VLOOKUP(L19,Ubicacion!A:AE,31,FALSE) -> 1 | AM19: =IF(T19=0,"100%",AV19/T19) -> 0.66666667 | AN19: =IF(U19=0,"100%",AW19/U19) -> 0.5 | AO19: =IF(V19=0,"100%",AX19/V19) -> 1 | AP19: =IF(W19=0,"100%",AY19/W19) -> 0.15384615 | AQ19: =IF(X19=0,"100%",AZ19/X19) -> 0.5 | AR19: =IF(Y19=0,"100%",BA19/Y19) -> 0.25 | AS19: =IF(Z19=0,"100%",BB19/Z19) -> 100% | AT19: =IF(AA19=0,"100%",BC19/AA19) -> 100% | AU19: =IF(AB19=0,"100%",BD19/AB19) -> 100% | AV19: 10 | AW19: 1 | AX19: 2 | AY19: 2 | AZ19: 2 | BA19: 1 | BB19: 2 | BC19: 1 | BD19: 1 | BE19: NO OK | BF19: NO OK | BG19: OK | BH19: OK | BI19: OK | BJ19: OK | BN19: =IF(AND((BN$6-$P19)>=0,(BN$6-$P19)<=($Q19-$P19)),"."," ") | BO19: =IF(AND((BO$6-$P19)>=0,(BO$6-$P19)<=($Q19-$P19)),"."," ") | BP19: =IF(AND((BP$6-$P19)>=0,(BP$6-$P19)<=($Q19-$P19)),"."," ") | BQ19: =IF(AND((BQ$6-$P19)>=0,(BQ$6-$P19)<=($Q19-$P19)),"."," ") | BR19: =IF(AND((BR$6-$P19)>=0,(BR$6-$P19)<=($Q19-$P19)),"."," ") | BS19: =IF(AND((BS$6-$P19)>=0,(BS$6-$P19)<=($Q19-$P19)),"."," ") | BT19: =IF(AND((BT$6-$P19)>=0,(BT$6-$P19)<=($Q19-$P19)),"."," ") | BU19: =IF(AND((BU$6-$P19)>=0,(BU$6-$P19)<=($Q19-$P19)),"."," ") | ... CR19: =IF(AND((CR$6-$P19)>=0,(CR$6-$P19)<=($Q19-$P19)),"."," ")
... A87: =VLOOKUP(L87,Ubicacion!A:K,2,FALSE) -> LI3BR | B87: =VLOOKUP(L87,Ubicacion!A:K,3,FALSE) -> LI3BC12 | C87: =VLOOKUP(L87,Ubicacion!A:K,4,FALSE) -> LIMA | D87: =VLOOKUP(L87,Ubicacion!A:K,5,FALSE) -> BARRANCO | E87: =VLOOKUP(L87,Ubicacion!A:K,6,FALSE) -> Mercado | F87: =VLOOKUP(L87,Ubicacion!A:K,7,FALSE) -> 10:00 - 16:00 | G87: =VLOOKUP(L87,Ubicacion!A:K,8,FALSE) -> WEDNESDAY | H87: =VLOOKUP(L87,Ubicacion!A:K,9,FALSE) -> 2 | I87: =VLOOKUP(L87,Ubicacion!A:K,10,FALSE) -> -12.137591 | J87: =VLOOKUP(L87,Ubicacion!A:K,11,FALSE) -> -77.022477 | K87: =P87&O87 -> 46161Grupo 4 | L87: CP81 | M87: 1 | N87: AF | O87: Grupo 4 | P87: 46161 | Q87: =P87+M87-1 -> 46161 | R87: =IF($A$1<Q87,"On-time",IF(AND(Q87<=$A$1,BJ87="OK"),"OK","NO OK")) -> On-time | S87: =(UPPER(TEXT(P87,"dddd"))) -> TUESDAY | T87: =VLOOKUP(L87,Ubicacion!A:AE,13,FALSE) -> 15 | U87: =VLOOKUP(L87,Ubicacion!A:AE,14,FALSE) -> 0 | V87: =VLOOKUP(L87,Ubicacion!A:AE,15,FALSE) -> 10 | W87: =VLOOKUP(L87,Ubicacion!A:AE,16,FALSE) -> 2 | X87: =VLOOKUP(L87,Ubicacion!A:AE,17,FALSE) -> 2 | Y87: =VLOOKUP(L87,Ubicacion!A:AE,18,FALSE) -> 0 | Z87: =VLOOKUP(L87,Ubicacion!A:AE,19,FALSE) -> 0 | AA87: =VLOOKUP(L87,Ubicacion!A:AE,20,FALSE) -> 0 | AB87: =VLOOKUP(L87,Ubicacion!A:AE,21,FALSE) -> 0 | AC87: =VLOOKUP(L87,Ubicacion!A:AE,22,FALSE) -> 4 | AD87: =VLOOKUP(L87,Ubicacion!A:AE,23,FALSE) -> 80 | AE87: =VLOOKUP(L87,Ubicacion!A:AE,24,FALSE) -> 0 | AF87: =VLOOKUP(L87,Ubicacion!A:AE,25,FALSE) -> 0 | AG87: =VLOOKUP(L87,Ubicacion!A:AE,26,FALSE) -> 84 | AH87: =VLOOKUP(L87,Ubicacion!A:AE,27,FALSE) -> 2 | AI87: =VLOOKUP(L87,Ubicacion!A:AE,28,FALSE) -> 5 | AJ87: =VLOOKUP(L87,Ubicacion!A:AE,29,FALSE) -> 3 | AK87: =VLOOKUP(L87,Ubicacion!A:AE,30,FALSE) -> 1 | AL87: =VLOOKUP(L87,Ubicacion!A:AE,31,FALSE) -> 1 | AM87: =IF(T87=0,"100%",AV87/T87) -> 0.66666667 | AN87: =IF(U87=0,"100%",AW87/U87) -> 100% | AO87: =IF(V87=0,"100%",AX87/V87) -> 0.2 | AP87: =IF(W87=0,"100%",AY87/W87) -> 1 | AQ87: =IF(X87=0,"100%",AZ87/X87) -> 1 | AR87: =IF(Y87=0,"100%",BA87/Y87) -> 100% | AS87: =IF(Z87=0,"100%",BB87/Z87) -> 100% | AT87: =IF(AA87=0,"100%",BC87/AA87) -> 100% | AU87: =IF(AB87=0,"100%",BD87/AB87) -> 100% | AV87: 10 | AW87: 1 | AX87: 2 | AY87: 2 | AZ87: 2 | BA87: 1 | BB87: 2 | BC87: 1 | BD87: 1 | BE87: NO OK | BF87: NO OK | BG87: OK | BH87: OK | BI87: OK | BJ87: OK | BN87: =IF(AND((BN$6-$P87)>=0,(BN$6-$P87)<=($Q87-$P87)),"."," ") | BO87: =IF(AND((BO$6-$P87)>=0,(BO$6-$P87)<=($Q87-$P87)),"."," ") | BP87: =IF(AND((BP$6-$P87)>=0,(BP$6-$P87)<=($Q87-$P87)),"."," ") | BQ87: =IF(AND((BQ$6-$P87)>=0,(BQ$6-$P87)<=($Q87-$P87)),"."," ") | BR87: =IF(AND((BR$6-$P87)>=0,(BR$6-$P87)<=($Q87-$P87)),"."," ") | BS87: =IF(AND((BS$6-$P87)>=0,(BS$6-$P87)<=($Q87-$P87)),"."," ") | BT87: =IF(AND((BT$6-$P87)>=0,(BT$6-$P87)<=($Q87-$P87)),"."," ") | BU87: =IF(AND((BU$6-$P87)>=0,(BU$6-$P87)<=($Q87-$P87)),"."," ") | ... CR87: =IF(AND((CR$6-$P87)>=0,(CR$6-$P87)<=($Q87-$P87)),"."," ")
K88: =P88&O88 | BN88: =IF(AND((BN$6-$P88)>=0,(BN$6-$P88)<=($Q88-$P88)),"."," ") | BO88: =IF(AND((BO$6-$P88)>=0,(BO$6-$P88)<=($Q88-$P88)),"."," ") | BP88: =IF(AND((BP$6-$P88)>=0,(BP$6-$P88)<=($Q88-$P88)),"."," ") | BQ88: =IF(AND((BQ$6-$P88)>=0,(BQ$6-$P88)<=($Q88-$P88)),"."," ") | BR88: =IF(AND((BR$6-$P88)>=0,(BR$6-$P88)<=($Q88-$P88)),"."," ") | BS88: =IF(AND((BS$6-$P88)>=0,(BS$6-$P88)<=($Q88-$P88)),"."," ") | BT88: =IF(AND((BT$6-$P88)>=0,(BT$6-$P88)<=($Q88-$P88)),"."," ") | BU88: =IF(AND((BU$6-$P88)>=0,(BU$6-$P88)<=($Q88-$P88)),"."," ") | ... CR88: =IF(AND((CR$6-$P88)>=0,(CR$6-$P88)<=($Q88-$P88)),"."," ")
K89: =P89&O89 | BN89: =IF(AND((BN$6-$P89)>=0,(BN$6-$P89)<=($Q89-$P89)),"."," ") | BO89: =IF(AND((BO$6-$P89)>=0,(BO$6-$P89)<=($Q89-$P89)),"."," ") | BP89: =IF(AND((BP$6-$P89)>=0,(BP$6-$P89)<=($Q89-$P89)),"."," ") | BQ89: =IF(AND((BQ$6-$P89)>=0,(BQ$6-$P89)<=($Q89-$P89)),"."," ") | BR89: =IF(AND((BR$6-$P89)>=0,(BR$6-$P89)<=($Q89-$P89)),"."," ") | BS89: =IF(AND((BS$6-$P89)>=0,(BS$6-$P89)<=($Q89-$P89)),"."," ") | BT89: =IF(AND((BT$6-$P89)>=0,(BT$6-$P89)<=($Q89-$P89)),"."," ") | BU89: =IF(AND((BU$6-$P89)>=0,(BU$6-$P89)<=($Q89-$P89)),"."," ") | ... CR89: =IF(AND((CR$6-$P89)>=0,(CR$6-$P89)<=($Q89-$P89)),"."," ")

Sheet PR Grupo
A1: 46143
I2: No Tocar | K2: =TEXT(K3,"ddd") -> Fri | L2: =TEXT(L3,"ddd") -> Sat | M2: =TEXT(M3,"ddd") -> Sun | N2: =TEXT(N3,"ddd") -> Mon | O2: =TEXT(O3,"ddd") -> Tue | P2: =TEXT(P3,"ddd") -> Wed | Q2: =TEXT(Q3,"ddd") -> Thu | R2: =TEXT(R3,"ddd") -> Fri | ... AO2: =TEXT(AO3,"ddd") -> Sun
A3: BR | B3: BC | C3: PR Code | D3: owner_code | E3: Tipo de PR | F3: Leader (AF/BC) | G3: Grupo | H3: KPI Trabajo | I3: Cantidad Dia de Trabajo | J3: OK/NO OK | K3: =A1 -> 46143 | L3: =K3+1 -> 46144 | M3: =L3+1 -> 46145 | N3: =M3+1 -> 46146 | O3: =N3+1 -> 46147 | P3: =O3+1 -> 46148 | Q3: =P3+1 -> 46149 | R3: =Q3+1 -> 46150 | S3: =R3+1 -> 46151 | ... AO3: =AN3+1 -> 46173
A4: LI3BR | B4: LI3BC03 | C4: LI3PR10116 | D4: AF_ANACC_LI3 | E4: Exclusive | F4: AF_ANACC_LI3 | G4: LI3PR10136 | H4: 25 | I4: =DAY(EOMONTH($A$1,0))-COUNTIFS(K4:AO4,0) -> 10 | J4: =IF(I4<H4,"NO OK","OK") -> NO OK | K4: =IF(COUNTIFS('Plan CP'!$O:$O,'PR Grupo'!$G4,'Plan CP'!$P:$P,'PR Grupo'!K$3,'Plan CP'!$M:$M,1)=1,1,IF(IFERROR(VLOOKUP('PR Grupo'!K$3&'PR Grupo'!$G4,'Plan CP'!$K:$P,3,FALSE)>1,0),IFERROR(VLOOKUP('PR Grupo'!K$3&'PR Grupo'!$G4,'Plan CP'!$K:$P,3,FALSE),0),0)) -> 10 | L4: =IF(K4>1,K4-1,IF(COUNTIFS('Plan CP'!$O:$O,'PR Grupo'!$G4,'Plan CP'!$P:$P,'PR Grupo'!L$3,'Plan CP'!$M:$M,1)=1,1,IF(IFERROR(VLOOKUP('PR Grupo'!L$3&'PR Grupo'!$G4,'Plan CP'!$K:$P,3,FALSE)>1,0),IFERROR(VLOOKUP('PR Grupo'!L$3&'PR Grupo'!$G4,'Plan CP'!$K:$P,3,FALSE),0),0))) -> 9 | M4: =IF(L4>1,L4-1,IF(COUNTIFS('Plan CP'!$O:$O,'PR Grupo'!$G4,'Plan CP'!$P:$P,'PR Grupo'!M$3,'Plan CP'!$M:$M,1)=1,1,IF(IFERROR(VLOOKUP('PR Grupo'!M$3&'PR Grupo'!$G4,'Plan CP'!$K:$P,3,FALSE)>1,0),IFERROR(VLOOKUP('PR Grupo'!M$3&'PR Grupo'!$G4,'Plan CP'!$K:$P,3,FALSE),0),0))) -> 8 | N4: =IF(M4>1,M4-1,IF(COUNTIFS('Plan CP'!$O:$O,'PR Grupo'!$G4,'Plan CP'!$P:$P,'PR Grupo'!N$3,'Plan CP'!$M:$M,1)=1,1,IF(IFERROR(VLOOKUP('PR Grupo'!N$3&'PR Grupo'!$G4,'Plan CP'!$K:$P,3,FALSE)>1,0),IFERROR(VLOOKUP('PR Grupo'!N$3&'PR Grupo'!$G4,'Plan CP'!$K:$P,3,FALSE),0),0))) -> 7 | O4: =IF(N4>1,N4-1,IF(COUNTIFS('Plan CP'!$O:$O,'PR Grupo'!$G4,'Plan CP'!$P:$P,'PR Grupo'!O$3,'Plan CP'!$M:$M,1)=1,1,IF(IFERROR(VLOOKUP('PR Grupo'!O$3&'PR Grupo'!$G4,'Plan CP'!$K:$P,3,FALSE)>1,0),IFERROR(VLOOKUP('PR Grupo'!O$3&'PR Grupo'!$G4,'Plan CP'!$K:$P,3,FALSE),0),0))) -> 6 | P4: =IF(O4>1,O4-1,IF(COUNTIFS('Plan CP'!$O:$O,'PR Grupo'!$G4,'Plan CP'!$P:$P,'PR Grupo'!P$3,'Plan CP'!$M:$M,1)=1,1,IF(IFERROR(VLOOKUP('PR Grupo'!P$3&'PR Grupo'!$G4,'Plan CP'!$K:$P,3,FALSE)>1,0),IFERROR(VLOOKUP('PR Grupo'!P$3&'PR Grupo'!$G4,'Plan CP'!$K:$P,3,FALSE),0),0))) -> 5 | Q4: =IF(P4>1,P4-1,IF(COUNTIFS('Plan CP'!$O:$O,'PR Grupo'!$G4,'Plan CP'!$P:$P,'PR Grupo'!Q$3,'Plan CP'!$M:$M,1)=1,1,IF(IFERROR(VLOOKUP('PR Grupo'!Q$3&'PR Grupo'!$G4,'Plan CP'!$K:$P,3,FALSE)>1,0),IFERROR(VLOOKUP('PR Grupo'!Q$3&'PR Grupo'!$G4,'Plan CP'!$K:$P,3,FALSE),0),0))) -> 4 | R4: =IF(Q4>1,Q4-1,IF(COUNTIFS('Plan CP'!$O:$O,'PR Grupo'!$G4,'Plan CP'!$P:$P,'PR Grupo'!R$3,'Plan CP'!$M:$M,1)=1,1,IF(IFERROR(VLOOKUP('PR Grupo'!R$3&'PR Grupo'!$G4,'Plan CP'!$K:$P,3,FALSE)>1,0),IFERROR(VLOOKUP('PR Grupo'!R$3&'PR Grupo'!$G4,'Plan CP'!$K:$P,3,FALSE),0),0))) -> 3 | S4: =IF(R4>1,R4-1,IF(COUNTIFS('Plan CP'!$O:$O,'PR Grupo'!$G4,'Plan CP'!$P:$P,'PR Grupo'!S$3,'Plan CP'!$M:$M,1)=1,1,IF(IFERROR(VLOOKUP('PR Grupo'!S$3&'PR Grupo'!$G4,'Plan CP'!$K:$P,3,FALSE)>1,0),IFERROR(VLOOKUP('PR Grupo'!S$3&'PR Grupo'!$G4,'Plan CP'!$K:$P,3,FALSE),0),0))) -> 2 | ... AO4: =IF(AN4>1,AN4-1,IF(COUNTIFS('Plan CP'!$O:$O,'PR Grupo'!$G4,'Plan CP'!$P:$P,'PR Grupo'!AO$3,'Plan CP'!$M:$M,1)=1,1,IF(IFERROR(VLOOKUP('PR Grupo'!AO$3&'PR Grupo'!$G4,'Plan CP'!$K:$P,3,FALSE)>1,0),IFERROR(VLOOKUP('PR Grupo'!AO$3&'PR Grupo'!$G4,'Plan CP'!$K:$P,3,FALSE),0),0))) -> 0
A5: LI3BR | B5: LI2BC13 | C5: LI3PR10204 | D5: AF_JHONBV_LI3 | E5: Nuevo | F5: AF_JHONBV_LI3 | G5: Grupo 1 | H5: 20 | I5: =DAY(EOMONTH($A$1,0))-COUNTIFS(K5:AO5,0) -> 18 | J5: =IF(I5<H5,"NO OK","OK") -> NO OK | K5: =IF(COUNTIFS('Plan CP'!$O:$O,'PR Grupo'!$G5,'Plan CP'!$P:$P,'PR Grupo'!K$3,'Plan CP'!$M:$M,1)=1,1,IF(IFERROR(VLOOKUP('PR Grupo'!K$3&'PR Grupo'!$G5,'Plan CP'!$K:$P,3,FALSE)>1,0),IFERROR(VLOOKUP('PR Grupo'!K$3&'PR Grupo'!$G5,'Plan CP'!$K:$P,3,FALSE),0),0)) -> 2 | L5: =IF(K5>1,K5-1,IF(COUNTIFS('Plan CP'!$O:$O,'PR Grupo'!$G5,'Plan CP'!$P:$P,'PR Grupo'!L$3,'Plan CP'!$M:$M,1)=1,1,IF(IFERROR(VLOOKUP('PR Grupo'!L$3&'PR Grupo'!$G5,'Plan CP'!$K:$P,3,FALSE)>1,0),IFERROR(VLOOKUP('PR Grupo'!L$3&'PR Grupo'!$G5,'Plan CP'!$K:$P,3,FALSE),0),0))) -> 1 | M5: =IF(L5>1,L5-1,IF(COUNTIFS('Plan CP'!$O:$O,'PR Grupo'!$G5,'Plan CP'!$P:$P,'PR Grupo'!M$3,'Plan CP'!$M:$M,1)=1,1,IF(IFERROR(VLOOKUP('PR Grupo'!M$3&'PR Grupo'!$G5,'Plan CP'!$K:$P,3,FALSE)>1,0),IFERROR(VLOOKUP('PR Grupo'!M$3&'PR Grupo'!$G5,'Plan CP'!$K:$P,3,FALSE),0),0))) -> 0 | N5: =IF(M5>1,M5-1,IF(COUNTIFS('Plan CP'!$O:$O,'PR Grupo'!$G5,'Plan CP'!$P:$P,'PR Grupo'!N$3,'Plan CP'!$M:$M,1)=1,1,IF(IFERROR(VLOOKUP('PR Grupo'!N$3&'PR Grupo'!$G5,'Plan CP'!$K:$P,3,FALSE)>1,0),IFERROR(VLOOKUP('PR Grupo'!N$3&'PR Grupo'!$G5,'Plan CP'!$K:$P,3,FALSE),0),0))) -> 1 | O5: =IF(N5>1,N5-1,IF(COUNTIFS('Plan CP'!$O:$O,'PR Grupo'!$G5,'Plan CP'!$P:$P,'PR Grupo'!O$3,'Plan CP'!$M:$M,1)=1,1,IF(IFERROR(VLOOKUP('PR Grupo'!O$3&'PR Grupo'!$G5,'Plan CP'!$K:$P,3,FALSE)>1,0),IFERROR(VLOOKUP('PR Grupo'!O$3&'PR Grupo'!$G5,'Plan CP'!$K:$P,3,FALSE),0),0))) -> 1 | P5: =IF(O5>1,O5-1,IF(COUNTIFS('Plan CP'!$O:$O,'PR Grupo'!$G5,'Plan CP'!$P:$P,'PR Grupo'!P$3,'Plan CP'!$M:$M,1)=1,1,IF(IFERROR(VLOOKUP('PR Grupo'!P$3&'PR Grupo'!$G5,'Plan CP'!$K:$P,3,FALSE)>1,0),IFERROR(VLOOKUP('PR Grupo'!P$3&'PR Grupo'!$G5,'Plan CP'!$K:$P,3,FALSE),0),0))) -> 1 | Q5: =IF(P5>1,P5-1,IF(COUNTIFS('Plan CP'!$O:$O,'PR Grupo'!$G5,'Plan CP'!$P:$P,'PR Grupo'!Q$3,'Plan CP'!$M:$M,1)=1,1,IF(IFERROR(VLOOKUP('PR Grupo'!Q$3&'PR Grupo'!$G5,'Plan CP'!$K:$P,3,FALSE)>1,0),IFERROR(VLOOKUP('PR Grupo'!Q$3&'PR Grupo'!$G5,'Plan CP'!$K:$P,3,FALSE),0),0))) -> 1 | R5: =IF(Q5>1,Q5-1,IF(COUNTIFS('Plan CP'!$O:$O,'PR Grupo'!$G5,'Plan CP'!$P:$P,'PR Grupo'!R$3,'Plan CP'!$M:$M,1)=1,1,IF(IFERROR(VLOOKUP('PR Grupo'!R$3&'PR Grupo'!$G5,'Plan CP'!$K:$P,3,FALSE)>1,0),IFERROR(VLOOKUP('PR Grupo'!R$3&'PR Grupo'!$G5,'Plan CP'!$K:$P,3,FALSE),0),0))) -> 1 | S5: =IF(R5>1,R5-1,IF(COUNTIFS('Plan CP'!$O:$O,'PR Grupo'!$G5,'Plan CP'!$P:$P,'PR Grupo'!S$3,'Plan CP'!$M:$M,1)=1,1,IF(IFERROR(VLOOKUP('PR Grupo'!S$3&'PR Grupo'!$G5,'Plan CP'!$K:$P,3,FALSE)>1,0),IFERROR(VLOOKUP('PR Grupo'!S$3&'PR Grupo'!$G5,'Plan CP'!$K:$P,3,FALSE),0),0))) -> 1 | ... AO5: =IF(AN5>1,AN5-1,IF(COUNTIFS('Plan CP'!$O:$O,'PR Grupo'!$G5,'Plan CP'!$P:$P,'PR Grupo'!AO$3,'Plan CP'!$M:$M,1)=1,1,IF(IFERROR(VLOOKUP('PR Grupo'!AO$3&'PR Grupo'!$G5,'Plan CP'!$K:$P,3,FALSE)>1,0),IFERROR(VLOOKUP('PR Grupo'!AO$3&'PR Grupo'!$G5,'Plan CP'!$K:$P,3,FALSE),0),0))) -> 0
